Workbook
Name Topology_Coding: Reference!$B$2:$B$10
Name Additional_Tasks: Reference!$D$2:$D$10
Name Field_Testing: Reference!$C$2:$C$10
Name Manual_TPfC: Reference!$A$2:$A$10

Sheet Anjali
A1: KW | B1: Holiday OR Weekend | C1: Day | D1: Date | E1: Project | F1: Task | G1: Duration (Hrs) | H1: No. of Signals | I1: Time per Signal (mins) | J1: Notes
A2: =WEEKNUM(D2,2) -> 18 | B2: =IF(OR(WEEKDAY(D2)=1, WEEKDAY(D2)=7), TEXT(D2, "dddd"), IF(COUNTIF(Reference!$A$13:$A$27, D2) > 0, "Holiday", TEXT(D2, "dddd"))) -> Holiday | C2: =TEXT(D2,"dddd") -> Friday | D2: 46143 | P2: =IF(ISBLANK(E2), "", TRANSPOSE(INDIRECT(E2)))
A3: =WEEKNUM(D3,2) -> 18 | B3: =IF(OR(WEEKDAY(D3)=1, WEEKDAY(D3)=7), TEXT(D3, "dddd"), IF(COUNTIF(Reference!$A$13:$A$27, D3) > 0, "Holiday", TEXT(D3, "dddd"))) -> Saturday | C3: =TEXT(D3,"dddd") -> Saturday | D3: 46144 | I3: =IFERROR((G3/H3)*60, "") | P3: =IF(ISBLANK(E3), "", TRANSPOSE(INDIRECT(E3)))
A4: =WEEKNUM(D4,2) -> 18 | B4: =IF(OR(WEEKDAY(D4)=1, WEEKDAY(D4)=7), TEXT(D4, "dddd"), IF(COUNTIF(Reference!$A$13:$A$27, D4) > 0, "Holiday", TEXT(D4, "dddd"))) -> Sunday | C4: =TEXT(D4,"dddd") -> Sunday | D4: 46145 | I4: =IFERROR((G4/H4)*60, "") | P4: =IF(ISBLANK(E4), "", TRANSPOSE(INDIRECT(E4)))
A5: =WEEKNUM(D5,2) -> 19 | B5: =IF(OR(WEEKDAY(D5)=1, WEEKDAY(D5)=7), TEXT(D5, "dddd"), IF(COUNTIF(Reference!$A$13:$A$27, D5) > 0, "Holiday", TEXT(D5, "dddd"))) -> Monday | C5: =TEXT(D5,"dddd") -> Monday | D5: 46146 | I5: =IFERROR((G5/H5)*60, "") | P5: =IF(ISBLANK(E5), "", TRANSPOSE(INDIRECT(E5)))
A6: =WEEKNUM(D6,2) -> 19 | B6: =IF(OR(WEEKDAY(D6)=1, WEEKDAY(D6)=7), TEXT(D6, "dddd"), IF(COUNTIF(Reference!$A$13:$A$27, D6) > 0, "Holiday", TEXT(D6, "dddd"))) -> Tuesday | C6: =TEXT(D6,"dddd") -> Tuesday | D6: 46147 | I6: =IFERROR((G6/H6)*60, "") | J6: Urlaub | P6: =IF(ISBLANK(E6), "", TRANSPOSE(INDIRECT(E6)))
A7: =WEEKNUM(D7,2) -> 19 | B7: =IF(OR(WEEKDAY(D7)=1, WEEKDAY(D7)=7), TEXT(D7, "dddd"), IF(COUNTIF(Reference!$A$13:$A$27, D7) > 0, "Holiday", TEXT(D7, "dddd"))) -> Wednesday | C7: =TEXT(D7,"dddd") -> Wednesday | D7: 46148 | I7: =IFERROR((G7/H7)*60, "") | J7: Urlaub | P7: =IF(ISBLANK(E7), "", TRANSPOSE(INDIRECT(E7)))
A8: =WEEKNUM(D8,2) -> 19 | B8: =IF(OR(WEEKDAY(D8)=1, WEEKDAY(D8)=7), TEXT(D8, "dddd"), IF(COUNTIF(Reference!$A$13:$A$27, D8) > 0, "Holiday", TEXT(D8, "dddd"))) -> Thursday | C8: =TEXT(D8,"dddd") -> Thursday | D8: 46149 | I8: =IFERROR((G8/H8)*60, "") | J8: Urlaub | P8: =IF(ISBLANK(E8), "", TRANSPOSE(INDIRECT(E8)))
A9: =WEEKNUM(D9,2) -> 19 | B9: =IF(OR(WEEKDAY(D9)=1, WEEKDAY(D9)=7), TEXT(D9, "dddd"), IF(COUNTIF(Reference!$A$13:$A$27, D9) > 0, "Holiday", TEXT(D9, "dddd"))) -> Friday | C9: =TEXT(D9,"dddd") -> Friday | D9: 46150 | I9: =IFERROR((G9/H9)*60, "") | P9: =IF(ISBLANK(E9), "", TRANSPOSE(INDIRECT(E9)))
A10: =WEEKNUM(D10,2) -> 19 | B10: =IF(OR(WEEKDAY(D10)=1, WEEKDAY(D10)=7), TEXT(D10, "dddd"), IF(COUNTIF(Reference!$A$13:$A$27, D10) > 0, "Holiday", TEXT(D10, "dddd"))) -> Saturday | C10: =TEXT(D10,"dddd") -> Saturday | D10: 46151 | I10: =IFERROR((G10/H10)*60, "") | P10: =IF(ISBLANK(E10), "", TRANSPOSE(INDIRECT(E10)))
A11: =WEEKNUM(D11,2) -> 19 | B11: =IF(OR(WEEKDAY(D11)=1, WEEKDAY(D11)=7), TEXT(D11, "dddd"), IF(COUNTIF(Reference!$A$13:$A$27, D11) > 0, "Holiday", TEXT(D11, "dddd"))) -> Sunday | C11: =TEXT(D11,"dddd") -> Sunday | D11: 46152 | I11: =IFERROR((G11/H11)*60, "") | P11: =IF(ISBLANK(E11), "", TRANSPOSE(INDIRECT(E11)))
A12: =WEEKNUM(D12,2) -> 20 | B12: =IF(OR(WEEKDAY(D12)=1, WEEKDAY(D12)=7), TEXT(D12, "dddd"), IF(COUNTIF(Reference!$A$13:$A$27, D12) > 0, "Holiday", TEXT(D12, "dddd"))) -> Monday | C12: =TEXT(D12,"dddd") -> Monday | D12: 46153 | I12: =IFERROR((G12/H12)*60, "") | P12: =IF(ISBLANK(E12), "", TRANSPOSE(INDIRECT(E12)))
A13: =WEEKNUM(D13,2) -> 20 | B13: =IF(OR(WEEKDAY(D13)=1, WEEKDAY(D13)=7), TEXT(D13, "dddd"), IF(COUNTIF(Reference!$A$13:$A$27, D13) > 0, "Holiday", TEXT(D13, "dddd"))) -> Tuesday | C13: =TEXT(D13,"dddd") -> Tuesday | D13: 46154 | E13: Topology_Coding | F13: Norway | G13: 8 | I13: =IFERROR((G13/H13)*60, "") | P13: =IF(ISBLANK(E13), "", TRANSPOSE(INDIRECT(E13))) -> Netherlands | Q13: Norway | R13: Switzerland | S13: UK
A14: =WEEKNUM(D14,2) -> 20 | B14: =IF(OR(WEEKDAY(D14)=1, WEEKDAY(D14)=7), TEXT(D14, "dddd"), IF(COUNTIF(Reference!$A$13:$A$27, D14) > 0, "Holiday", TEXT(D14, "dddd"))) -> Wednesday | C14: =TEXT(D14,"dddd") -> Wednesday | D14: 46155 | E14: Topology_Coding | F14: Norway | G14: 8 | I14: =IFERROR((G14/H14)*60, "") | P14: =IF(ISBLANK(E14), "", TRANSPOSE(INDIRECT(E14))) -> Netherlands | Q14: Norway | R14: Switzerland | S14: UK
A15: =WEEKNUM(D15,2) -> 20 | B15: =IF(OR(WEEKDAY(D15)=1, WEEKDAY(D15)=7), TEXT(D15, "dddd"), IF(COUNTIF(Reference!$A$13:$A$27, D15) > 0, "Holiday", TEXT(D15, "dddd"))) -> Holiday | C15: =TEXT(D15,"dddd") -> Thursday | D15: 46156 | I15: =IFERROR((G15/H15)*60, "") | P15: =IF(ISBLANK(E15), "", TRANSPOSE(INDIRECT(E15)))
A16: =WEEKNUM(D16,2) -> 20 | B16: =IF(OR(WEEKDAY(D16)=1, WEEKDAY(D16)=7), TEXT(D16, "dddd"), IF(COUNTIF(Reference!$A$13:$A$27, D16) > 0, "Holiday", TEXT(D16, "dddd"))) -> Friday | C16: =TEXT(D16,"dddd") -> Friday | D16: 46157 | E16: Topology_Coding | F16: Norway | G16: 4 | I16: =IFERROR((G16/H16)*60, "") | P16: =IF(ISBLANK(E16), "", TRANSPOSE(INDIRECT(E16))) -> Netherlands | Q16: Norway | R16: Switzerland | S16: UK
A17: =WEEKNUM(D17,2) -> 20 | B17: =IF(OR(WEEKDAY(D17)=1, WEEKDAY(D17)=7), TEXT(D17, "dddd"), IF(COUNTIF(Reference!$A$13:$A$27, D17) > 0, "Holiday", TEXT(D17, "dddd"))) -> Saturday | C17: =TEXT(D17,"dddd") -> Saturday | D17: 46158 | I17: =IFERROR((G17/H17)*60, "") | P17: =IF(ISBLANK(E17), "", TRANSPOSE(INDIRECT(E17)))
A18: =WEEKNUM(D18,2) -> 20 | B18: =IF(OR(WEEKDAY(D18)=1, WEEKDAY(D18)=7), TEXT(D18, "dddd"), IF(COUNTIF(Reference!$A$13:$A$27, D18) > 0, "Holiday", TEXT(D18, "dddd"))) -> Sunday | C18: =TEXT(D18,"dddd") -> Sunday | D18: 46159 | I18: =IFERROR((G18/H18)*60, "") | P18: =IF(ISBLANK(E18), "", TRANSPOSE(INDIRECT(E18)))
A19: =WEEKNUM(D19,2) -> 21 | B19: =IF(OR(WEEKDAY(D19)=1, WEEKDAY(D19)=7), TEXT(D19, "dddd"), IF(COUNTIF(Reference!$A$13:$A$27, D19) > 0, "Holiday", TEXT(D19, "dddd"))) -> Monday | C19: =TEXT(D19,"dddd") -> Monday | D19: 46160 | I19: =IFERROR((G19/H19)*60, "") | P19: =IF(ISBLANK(E19), "", TRANSPOSE(INDIRECT(E19)))
A20: =WEEKNUM(D20,2) -> 21 | B20: =IF(OR(WEEKDAY(D20)=1, WEEKDAY(D20)=7), TEXT(D20, "dddd"), IF(COUNTIF(Reference!$A$13:$A$27, D20) > 0, "Holiday", TEXT(D20, "dddd"))) -> Tuesday | C20: =TEXT(D20,"dddd") -> Tuesday | D20: 46161 | E20: Topology_Coding | F20: Norway | G20: 4 | I20: =IFERROR((G20/H20)*60, "") | P20: =IF(ISBLANK(E20), "", TRANSPOSE(INDIRECT(E20))) -> Netherlands | Q20: Norway | R20: Switzerland | S20: UK
A21: =WEEKNUM(D21,2) -> 21 | B21: =IF(OR(WEEKDAY(D21)=1, WEEKDAY(D21)=7), TEXT(D21, "dddd"), IF(COUNTIF(Reference!$A$13:$A$27, D21) > 0, "Holiday", TEXT(D21, "dddd"))) -> Wednesday | C21: =TEXT(D21,"dddd") -> Wednesday | D21: 46162 | E21: Topology_Coding | F21: Norway | G21: 8 | I21: =IFERROR((G21/H21)*60, "") | P21: =IF(ISBLANK(E21), "", TRANSPOSE(INDIRECT(E21))) -> Netherlands | Q21: Norway | R21: Switzerland | S21: UK
A22: =WEEKNUM(D22,2) -> 21 | B22: =IF(OR(WEEKDAY(D22)=1, WEEKDAY(D22)=7), TEXT(D22, "dddd"), IF(COUNTIF(Reference!$A$13:$A$27, D22) > 0, "Holiday", TEXT(D22, "dddd"))) -> Thursday | C22: =TEXT(D22,"dddd") -> Thursday | D22: 46163 | E22: Topology_Coding | F22: Norway | G22: 4 | I22: =IFERROR((G22/H22)*60, "") | P22: =IF(ISBLANK(E22), "", TRANSPOSE(INDIRECT(E22))) -> Netherlands | Q22: Norway | R22: Switzerland | S22: UK
A23: =WEEKNUM(D23,2) -> 21 | B23: =IF(OR(WEEKDAY(D23)=1, WEEKDAY(D23)=7), TEXT(D23, "dddd"), IF(COUNTIF(Reference!$A$13:$A$27, D23) > 0, "Holiday", TEXT(D23, "dddd"))) -> Friday | C23: =TEXT(D23,"dddd") -> Friday | D23: 46164 | E23: Topology_Coding | F23: Norway | G23: 4 | I23: =IFERROR((G23/H23)*60, "") | P23: =IF(ISBLANK(E23), "", TRANSPOSE(INDIRECT(E23))) -> Netherlands | Q23: Norway | R23: Switzerland | S23: UK
A24: =WEEKNUM(D24,2) -> 21 | B24: =IF(OR(WEEKDAY(D24)=1, WEEKDAY(D24)=7), TEXT(D24, "dddd"), IF(COUNTIF(Reference!$A$13:$A$27, D24) > 0, "Holiday", TEXT(D24, "dddd"))) -> Saturday | C24: =TEXT(D24,"dddd") -> Saturday | D24: 46165 | I24: =IFERROR((G24/H24)*60, "") | P24: =IF(ISBLANK(E24), "", TRANSPOSE(INDIRECT(E24)))
A25: =WEEKNUM(D25,2) -> 21 | B25: =IF(OR(WEEKDAY(D25)=1, WEEKDAY(D25)=7), TEXT(D25, "dddd"), IF(COUNTIF(Reference!$A$13:$A$27, D25) > 0, "Holiday", TEXT(D25, "dddd"))) -> Sunday | C25: =TEXT(D25,"dddd") -> Sunday | D25: 46166 | I25: =IFERROR((G25/H25)*60, "") | P25: =IF(ISBLANK(E25), "", TRANSPOSE(INDIRECT(E25)))
A26: =WEEKNUM(D26,2) -> 22 | B26: =IF(OR(WEEKDAY(D26)=1, WEEKDAY(D26)=7), TEXT(D26, "dddd"), IF(COUNTIF(Reference!$A$13:$A$27, D26) > 0, "Holiday", TEXT(D26, "dddd"))) -> Holiday | C26: =TEXT(D26,"dddd") -> Monday | D26: 46167 | I26: =IFERROR((G26/H26)*60, "") | P26: =IF(ISBLANK(E26), "", TRANSPOSE(INDIRECT(E26)))
A27: =WEEKNUM(D27,2) -> 22 | B27: =IF(OR(WEEKDAY(D27)=1, WEEKDAY(D27)=7), TEXT(D27, "dddd"), IF(COUNTIF(Reference!$A$13:$A$27, D27) > 0, "Holiday", TEXT(D27, "dddd"))) -> Tuesday | C27: =TEXT(D27,"dddd") -> Tuesday | D27: 46168 | E27: Topology_Coding | F27: Norway | G27: 4 | H27: 17 | I27: =IFERROR((G27/H27)*60, "") -> 14.117647 | P27: =IF(ISBLANK(E27), "", TRANSPOSE(INDIRECT(E27))) -> Netherlands | Q27: Norway | R27: Switzerland | S27: UK
A28: =WEEKNUM(D28,2) -> 22 | B28: =IF(OR(WEEKDAY(D28)=1, WEEKDAY(D28)=7), TEXT(D28, "dddd"), IF(COUNTIF(Reference!$A$13:$A$27, D28) > 0, "Holiday", TEXT(D28, "dddd"))) -> Wednesday | C28: =TEXT(D28,"dddd") -> Wednesday | D28: 46169 | E28: Topology_Coding | F28: Norway | G28: 4 | H28: 18 | I28: =IFERROR((G28/H28)*60, "") -> 13.333333 | P28: =IF(ISBLANK(E28), "", TRANSPOSE(INDIRECT(E28))) -> Netherlands | Q28: Norway | R28: Switzerland | S28: UK
A29: =WEEKNUM(D29,2) -> 22 | B29: =IF(OR(WEEKDAY(D29)=1, WEEKDAY(D29)=7), TEXT(D29, "dddd"), IF(COUNTIF(Reference!$A$13:$A$27, D29) > 0, "Holiday", TEXT(D29, "dddd"))) -> Thursday | C29: =TEXT(D29,"dddd") -> Thursday | D29: 46170 | E29: Topology_Coding | F29: Norway | G29: 8 | H29: 28 | I29: =IFERROR((G29/H29)*60, "") -> 17.142857 | P29: =IF(ISBLANK(E29), "", TRANSPOSE(INDIRECT(E29))) -> Netherlands | Q29: Norway | R29: Switzerland | S29: UK
A30: =WEEKNUM(D30,2) -> 22 | B30: =IF(OR(WEEKDAY(D30)=1, WEEKDAY(D30)=7), TEXT(D30, "dddd"), IF(COUNTIF(Reference!$A$13:$A$27, D30) > 0, "Holiday", TEXT(D30, "dddd"))) -> Friday | C30: =TEXT(D30,"dddd") -> Friday | D30: 46171 | I30: =IFERROR((G30/H30)*60, "") | P30: =IF(ISBLANK(E30), "", TRANSPOSE(INDIRECT(E30)))
A31: =WEEKNUM(D31,2) -> 22 | B31: =IF(OR(WEEKDAY(D31)=1, WEEKDAY(D31)=7), TEXT(D31, "dddd"), IF(COUNTIF(Reference!$A$13:$A$27, D31) > 0, "Holiday", TEXT(D31, "dddd"))) -> Saturday | C31: =TEXT(D31,"dddd") -> Saturday | D31: 46172 | I31: =IFERROR((G31/H31)*60, "") | P31: =IF(ISBLANK(E31), "", TRANSPOSE(INDIRECT(E31)))
A32: =WEEKNUM(D32,2) -> 22 | B32: =IF(OR(WEEKDAY(D32)=1, WEEKDAY(D32)=7), TEXT(D32, "dddd"), IF(COUNTIF(Reference!$A$13:$A$27, D32) > 0, "Holiday", TEXT(D32, "dddd"))) -> Sunday | C32: =TEXT(D32,"dddd") -> Sunday | D32: 46173 | I32: =IFERROR((G32/H32)*60, "") | P32: =IF(ISBLANK(E32), "", TRANSPOSE(INDIRECT(E32)))
A33: =WEEKNUM(D33,2) -> 23 | B33: =IF(OR(WEEKDAY(D33)=1, WEEKDAY(D33)=7), TEXT(D33, "dddd"), IF(COUNTIF(Reference!$A$13:$A$27, D33) > 0, "Holiday", TEXT(D33, "dddd"))) -> Monday | C33: =TEXT(D33,"dddd") -> Monday | D33: 46174 | E33: Topology_Coding | F33: Norway | G33: 4 | H33: 18 | I33: =IFERROR((G33/H33)*60, "") -> 13.333333 | P33: =IF(ISBLANK(E33), "", TRANSPOSE(INDIRECT(E33))) -> Netherlands | Q33: Norway | R33: Switzerland | S33: UK
A34: =WEEKNUM(D34,2) -> 23 | B34: =IF(OR(WEEKDAY(D34)=1, WEEKDAY(D34)=7), TEXT(D34, "dddd"), IF(COUNTIF(Reference!$A$13:$A$27, D34) > 0, "Holiday", TEXT(D34, "dddd"))) -> Tuesday | C34: =TEXT(D34,"dddd") -> Tuesday | D34: 46175 | E34: Topology_Coding | F34: Norway | G34: 4 | H34: 21 | I34: =IFERROR((G34/H34)*60, "") -> 11.428571 | P34: =IF(ISBLANK(E34), "", TRANSPOSE(INDIRECT(E34))) -> Netherlands | Q34: Norway | R34: Switzerland | S34: UK
A35: =WEEKNUM(D35,2) -> 23 | B35: =IF(OR(WEEKDAY(D35)=1, WEEKDAY(D35)=7), TEXT(D35, "dddd"), IF(COUNTIF(Reference!$A$13:$A$27, D35) > 0, "Holiday", TEXT(D35, "dddd"))) -> Wednesday | C35: =TEXT(D35,"dddd") -> Wednesday | D35: 46176 | E35: Topology_Coding | F35: Norway | G35: 8 | H35: 30 | I35: =IFERROR((G35/H35)*60, "") -> 16 | P35: =IF(ISBLANK(E35), "", TRANSPOSE(INDIRECT(E35))) -> Netherlands | Q35: Norway | R35: Switzerland | S35: UK
A36: =WEEKNUM(D36,2) -> 23 | B36: =IF(OR(WEEKDAY(D36)=1, WEEKDAY(D36)=7), TEXT(D36, "dddd"), IF(COUNTIF(Reference!$A$13:$A$27, D36) > 0, "Holiday", TEXT(D36, "dddd"))) -> Holiday | C36: =TEXT(D36,"dddd") -> Thursday | D36: 46177 | I36: =IFERROR((G36/H36)*60, "") | P36: =IF(ISBLANK(E36), "", TRANSPOSE(INDIRECT(E36)))
A37: =WEEKNUM(D37,2) -> 23 | B37: =IF(OR(WEEKDAY(D37)=1, WEEKDAY(D37)=7), TEXT(D37, "dddd"), IF(COUNTIF(Reference!$A$13:$A$27, D37) > 0, "Holiday", TEXT(D37, "dddd"))) -> Friday | C37: =TEXT(D37,"dddd") -> Friday | D37: 46178 | I37: =IFERROR((G37/H37)*60, "") | P37: =IF(ISBLANK(E37), "", TRANSPOSE(INDIRECT(E37)))
A38: =WEEKNUM(D38,2) -> 23 | B38: =IF(OR(WEEKDAY(D38)=1, WEEKDAY(D38)=7), TEXT(D38, "dddd"), IF(COUNTIF(Reference!$A$13:$A$27, D38) > 0, "Holiday", TEXT(D38, "dddd"))) -> Saturday | C38: =TEXT(D38,"dddd") -> Saturday | D38: 46179 | I38: =IFERROR((G38/H38)*60, "") | P38: =IF(ISBLANK(E38), "", TRANSPOSE(INDIRECT(E38)))
A39: =WEEKNUM(D39,2) -> 23 | B39: =IF(OR(WEEKDAY(D39)=1, WEEKDAY(D39)=7), TEXT(D39, "dddd"), IF(COUNTIF(Reference!$A$13:$A$27, D39) > 0, "Holiday", TEXT(D39, "dddd"))) -> Sunday | C39: =TEXT(D39,"dddd") -> Sunday | D39: 46180 | I39: =IFERROR((G39/H39)*60, "") | P39: =IF(ISBLANK(E39), "", TRANSPOSE(INDIRECT(E39)))
A40: =WEEKNUM(D40,2) -> 24 | B40: =IF(OR(WEEKDAY(D40)=1, WEEKDAY(D40)=7), TEXT(D40, "dddd"), IF(COUNTIF(Reference!$A$13:$A$27, D40) > 0, "Holiday", TEXT(D40, "dddd"))) -> Monday | C40: =TEXT(D40,"dddd") -> Monday | D40: 46181 | I40: =IFERROR((G40/H40)*60, "") | P40: =IF(ISBLANK(E40), "", TRANSPOSE(INDIRECT(E40)))
...

Sheet Dhara
A1: KW | B1: Holiday OR Weekend | C1: Day | D1: Date | E1: Project | F1: Task | G1: Duration (Hrs) | H1: # of Signals | I1: Time per Signal (mins) | J1: Notes
A2: =WEEKNUM(D2,2) -> 18 | B2: =IF(OR(WEEKDAY(D2)=1, WEEKDAY(D2)=7), TEXT(D2, "dddd"), IF(COUNTIF(Reference!$A$13:$A$27, D2) > 0, "Holiday", TEXT(D2, "dddd"))) -> Holiday | C2: =TEXT(D2,"dddd") -> Friday | D2: 46143 | P2: =IF(ISBLANK(E2), "", TRANSPOSE(INDIRECT(E2)))
A3: =WEEKNUM(D3,2) -> 18 | B3: =IF(OR(WEEKDAY(D3)=1, WEEKDAY(D3)=7), TEXT(D3, "dddd"), IF(COUNTIF(Reference!$A$13:$A$27, D3) > 0, "Holiday", TEXT(D3, "dddd"))) -> Saturday | C3: =TEXT(D3,"dddd") -> Saturday | D3: 46144 | I3: =IFERROR((G3/H3)*60, "") | P3: =IF(ISBLANK(E3), "", TRANSPOSE(INDIRECT(E3)))
A4: =WEEKNUM(D4,2) -> 18 | B4: =IF(OR(WEEKDAY(D4)=1, WEEKDAY(D4)=7), TEXT(D4, "dddd"), IF(COUNTIF(Reference!$A$13:$A$27, D4) > 0, "Holiday", TEXT(D4, "dddd"))) -> Sunday | C4: =TEXT(D4,"dddd") -> Sunday | D4: 46145 | I4: =IFERROR((G4/H4)*60, "") | P4: =IF(ISBLANK(E4), "", TRANSPOSE(INDIRECT(E4)))
A5: =WEEKNUM(D5,2) -> 19 | B5: =IF(OR(WEEKDAY(D5)=1, WEEKDAY(D5)=7), TEXT(D5, "dddd"), IF(COUNTIF(Reference!$A$13:$A$27, D5) > 0, "Holiday", TEXT(D5, "dddd"))) -> Monday | C5: =TEXT(D5,"dddd") -> Monday | D5: 46146 | E5: Manual_TPfC | F5: TPfC Phase 3 | G5: 8 | H5: 16 | I5: =IFERROR((G5/H5)*60, "") -> 30 | P5: =IF(ISBLANK(E5), "", TRANSPOSE(INDIRECT(E5))) -> TPfC Phase 3 | Q5: TPfC Phase 4
A6: =WEEKNUM(D6,2) -> 19 | B6: =IF(OR(WEEKDAY(D6)=1, WEEKDAY(D6)=7), TEXT(D6, "dddd"), IF(COUNTIF(Reference!$A$13:$A$27, D6) > 0, "Holiday", TEXT(D6, "dddd"))) -> Tuesday | C6: =TEXT(D6,"dddd") -> Tuesday | D6: 46147 | E6: Manual_TPfC | F6: TPfC Phase 3 | G6: 4 | H6: 9 | I6: =IFERROR((G6/H6)*60, "") -> 26.666667 | P6: =IF(ISBLANK(E6), "", TRANSPOSE(INDIRECT(E6))) -> TPfC Phase 3 | Q6: TPfC Phase 4
A7: =WEEKNUM(D7,2) -> 19 | B7: =IF(OR(WEEKDAY(D7)=1, WEEKDAY(D7)=7), TEXT(D7, "dddd"), IF(COUNTIF(Reference!$A$13:$A$27, D7) > 0, "Holiday", TEXT(D7, "dddd"))) -> Wednesday | C7: =TEXT(D7,"dddd") -> Wednesday | D7: 46148 | E7: Manual_TPfC | F7: TPfC Phase 3 | G7: 8 | H7: 13 | I7: =IFERROR((G7/H7)*60, "") -> 36.923077 | P7: =IF(ISBLANK(E7), "", TRANSPOSE(INDIRECT(E7))) -> TPfC Phase 3 | Q7: TPfC Phase 4
A8: =WEEKNUM(D8,2) -> 19 | B8: =IF(OR(WEEKDAY(D8)=1, WEEKDAY(D8)=7), TEXT(D8, "dddd"), IF(COUNTIF(Reference!$A$13:$A$27, D8) > 0, "Holiday", TEXT(D8, "dddd"))) -> Thursday | C8: =TEXT(D8,"dddd") -> Thursday | D8: 46149 | I8: =IFERROR((G8/H8)*60, "") | P8: =IF(ISBLANK(E8), "", TRANSPOSE(INDIRECT(E8)))
A9: =WEEKNUM(D9,2) -> 19 | B9: =IF(OR(WEEKDAY(D9)=1, WEEKDAY(D9)=7), TEXT(D9, "dddd"), IF(COUNTIF(Reference!$A$13:$A$27, D9) > 0, "Holiday", TEXT(D9, "dddd"))) -> Friday | C9: =TEXT(D9,"dddd") -> Friday | D9: 46150 | I9: =IFERROR((G9/H9)*60, "") | P9: =IF(ISBLANK(E9), "", TRANSPOSE(INDIRECT(E9)))
A10: =WEEKNUM(D10,2) -> 19 | B10: =IF(OR(WEEKDAY(D10)=1, WEEKDAY(D10)=7), TEXT(D10, "dddd"), IF(COUNTIF(Reference!$A$13:$A$27, D10) > 0, "Holiday", TEXT(D10, "dddd"))) -> Saturday | C10: =TEXT(D10,"dddd") -> Saturday | D10: 46151 | I10: =IFERROR((G10/H10)*60, "") | P10: =IF(ISBLANK(E10), "", TRANSPOSE(INDIRECT(E10)))
A11: =WEEKNUM(D11,2) -> 19 | B11: =IF(OR(WEEKDAY(D11)=1, WEEKDAY(D11)=7), TEXT(D11, "dddd"), IF(COUNTIF(Reference!$A$13:$A$27, D11) > 0, "Holiday", TEXT(D11, "dddd"))) -> Sunday | C11: =TEXT(D11,"dddd") -> Sunday | D11: 46152 | I11: =IFERROR((G11/H11)*60, "") | P11: =IF(ISBLANK(E11), "", TRANSPOSE(INDIRECT(E11)))
A12: =WEEKNUM(D12,2) -> 20 | B12: =IF(OR(WEEKDAY(D12)=1, WEEKDAY(D12)=7), TEXT(D12, "dddd"), IF(COUNTIF(Reference!$A$13:$A$27, D12) > 0, "Holiday", TEXT(D12, "dddd"))) -> Monday | C12: =TEXT(D12,"dddd") -> Monday | D12: 46153 | E12: Manual_TPfC | F12: TPfC Phase 3 | G12: 8 | H12: 13 | I12: =IFERROR((G12/H12)*60, "") -> 36.923077 | P12: =IF(ISBLANK(E12), "", TRANSPOSE(INDIRECT(E12))) -> TPfC Phase 3 | Q12: TPfC Phase 4
A13: =WEEKNUM(D13,2) -> 20 | B13: =IF(OR(WEEKDAY(D13)=1, WEEKDAY(D13)=7), TEXT(D13, "dddd"), IF(COUNTIF(Reference!$A$13:$A$27, D13) > 0, "Holiday", TEXT(D13, "dddd"))) -> Tuesday | C13: =TEXT(D13,"dddd") -> Tuesday | D13: 46154 | E13: Manual_TPfC | F13: TPfC Phase 3 | G13: 8 | H13: 12 | I13: =IFERROR((G13/H13)*60, "") -> 40 | P13: =IF(ISBLANK(E13), "", TRANSPOSE(INDIRECT(E13))) -> TPfC Phase 3 | Q13: TPfC Phase 4
A14: =WEEKNUM(D14,2) -> 20 | B14: =IF(OR(WEEKDAY(D14)=1, WEEKDAY(D14)=7), TEXT(D14, "dddd"), IF(COUNTIF(Reference!$A$13:$A$27, D14) > 0, "Holiday", TEXT(D14, "dddd"))) -> Wednesday | C14: =TEXT(D14,"dddd") -> Wednesday | D14: 46155 | E14: Manual_TPfC | F14: TPfC Phase 3 | G14: 4 | H14: 10 | I14: =IFERROR((G14/H14)*60, "") -> 24 | P14: =IF(ISBLANK(E14), "", TRANSPOSE(INDIRECT(E14))) -> TPfC Phase 3 | Q14: TPfC Phase 4
A15: =WEEKNUM(D15,2) -> 20 | B15: =IF(OR(WEEKDAY(D15)=1, WEEKDAY(D15)=7), TEXT(D15, "dddd"), IF(COUNTIF(Reference!$A$13:$A$27, D15) > 0, "Holiday", TEXT(D15, "dddd"))) -> Holiday | C15: =TEXT(D15,"dddd") -> Thursday | D15: 46156 | I15: =IFERROR((G15/H15)*60, "") | P15: =IF(ISBLANK(E15), "", TRANSPOSE(INDIRECT(E15)))
A16: =WEEKNUM(D16,2) -> 20 | B16: =IF(OR(WEEKDAY(D16)=1, WEEKDAY(D16)=7), TEXT(D16, "dddd"), IF(COUNTIF(Reference!$A$13:$A$27, D16) > 0, "Holiday", TEXT(D16, "dddd"))) -> Friday | C16: =TEXT(D16,"dddd") -> Friday | D16: 46157 | I16: =IFERROR((G16/H16)*60, "") | P16: =IF(ISBLANK(E16), "", TRANSPOSE(INDIRECT(E16)))
A17: =WEEKNUM(D17,2) -> 20 | B17: =IF(OR(WEEKDAY(D17)=1, WEEKDAY(D17)=7), TEXT(D17, "dddd"), IF(COUNTIF(Reference!$A$13:$A$27, D17) > 0, "Holiday", TEXT(D17, "dddd"))) -> Saturday | C17: =TEXT(D17,"dddd") -> Saturday | D17: 46158 | I17: =IFERROR((G17/H17)*60, "") | P17: =IF(ISBLANK(E17), "", TRANSPOSE(INDIRECT(E17)))
A18: =WEEKNUM(D18,2) -> 20 | B18: =IF(OR(WEEKDAY(D18)=1, WEEKDAY(D18)=7), TEXT(D18, "dddd"), IF(COUNTIF(Reference!$A$13:$A$27, D18) > 0, "Holiday", TEXT(D18, "dddd"))) -> Sunday | C18: =TEXT(D18,"dddd") -> Sunday | D18: 46159 | I18: =IFERROR((G18/H18)*60, "") | P18: =IF(ISBLANK(E18), "", TRANSPOSE(INDIRECT(E18)))
A19: =WEEKNUM(D19,2) -> 21 | B19: =IF(OR(WEEKDAY(D19)=1, WEEKDAY(D19)=7), TEXT(D19, "dddd"), IF(COUNTIF(Reference!$A$13:$A$27, D19) > 0, "Holiday", TEXT(D19, "dddd"))) -> Monday | C19: =TEXT(D19,"dddd") -> Monday | D19: 46160 | I19: =IFERROR((G19/H19)*60, "") | P19: =IF(ISBLANK(E19), "", TRANSPOSE(INDIRECT(E19)))
A20: =WEEKNUM(D20,2) -> 21 | B20: =IF(OR(WEEKDAY(D20)=1, WEEKDAY(D20)=7), TEXT(D20, "dddd"), IF(COUNTIF(Reference!$A$13:$A$27, D20) > 0, "Holiday", TEXT(D20, "dddd"))) -> Tuesday | C20: =TEXT(D20,"dddd") -> Tuesday | D20: 46161 | E20: Manual_TPfC | F20: TPfC Phase 3 | G20: 8 | H20: 12 | I20: =IFERROR((G20/H20)*60, "") -> 40 | P20: =IF(ISBLANK(E20), "", TRANSPOSE(INDIRECT(E20))) -> TPfC Phase 3 | Q20: TPfC Phase 4
A21: =WEEKNUM(D21,2) -> 21 | B21: =IF(OR(WEEKDAY(D21)=1, WEEKDAY(D21)=7), TEXT(D21, "dddd"), IF(COUNTIF(Reference!$A$13:$A$27, D21) > 0, "Holiday", TEXT(D21, "dddd"))) -> Wednesday | C21: =TEXT(D21,"dddd") -> Wednesday | D21: 46162 | E21: Manual_TPfC | F21: TPfC Phase 3 | G21: 4 | H21: 9 | I21: =IFERROR((G21/H21)*60, "") -> 26.666667 | P21: =IF(ISBLANK(E21), "", TRANSPOSE(INDIRECT(E21))) -> TPfC Phase 3 | Q21: TPfC Phase 4
A22: =WEEKNUM(D22,2) -> 21 | B22: =IF(OR(WEEKDAY(D22)=1, WEEKDAY(D22)=7), TEXT(D22, "dddd"), IF(COUNTIF(Reference!$A$13:$A$27, D22) > 0, "Holiday", TEXT(D22, "dddd"))) -> Thursday | C22: =TEXT(D22,"dddd") -> Thursday | D22: 46163 | E22: Manual_TPfC | F22: TPfC Phase 3 | G22: 4 | H22: 6 | I22: =IFERROR((G22/H22)*60, "") -> 40 | P22: =IF(ISBLANK(E22), "", TRANSPOSE(INDIRECT(E22))) -> TPfC Phase 3 | Q22: TPfC Phase 4
A23: =WEEKNUM(D23,2) -> 21 | B23: =IF(OR(WEEKDAY(D23)=1, WEEKDAY(D23)=7), TEXT(D23, "dddd"), IF(COUNTIF(Reference!$A$13:$A$27, D23) > 0, "Holiday", TEXT(D23, "dddd"))) -> Friday | C23: =TEXT(D23,"dddd") -> Friday | D23: 46164 | E23: Manual_TPfC | F23: TPfC Phase 3 | G23: 4 | H23: 10 | I23: =IFERROR((G23/H23)*60, "") -> 24 | P23: =IF(ISBLANK(E23), "", TRANSPOSE(INDIRECT(E23))) -> TPfC Phase 3 | Q23: TPfC Phase 4
A24: =WEEKNUM(D24,2) -> 21 | B24: =IF(OR(WEEKDAY(D24)=1, WEEKDAY(D24)=7), TEXT(D24, "dddd"), IF(COUNTIF(Reference!$A$13:$A$27, D24) > 0, "Holiday", TEXT(D24, "dddd"))) -> Saturday | C24: =TEXT(D24,"dddd") -> Saturday | D24: 46165 | I24: =IFERROR((G24/H24)*60, "") | P24: =IF(ISBLANK(E24), "", TRANSPOSE(INDIRECT(E24)))
A25: =WEEKNUM(D25,2) -> 21 | B25: =IF(OR(WEEKDAY(D25)=1, WEEKDAY(D25)=7), TEXT(D25, "dddd"), IF(COUNTIF(Reference!$A$13:$A$27, D25) > 0, "Holiday", TEXT(D25, "dddd"))) -> Sunday | C25: =TEXT(D25,"dddd") -> Sunday | D25: 46166 | I25: =IFERROR((G25/H25)*60, "") | P25: =IF(ISBLANK(E25), "", TRANSPOSE(INDIRECT(E25)))
A26: =WEEKNUM(D26,2) -> 22 | B26: =IF(OR(WEEKDAY(D26)=1, WEEKDAY(D26)=7), TEXT(D26, "dddd"), IF(COUNTIF(Reference!$A$13:$A$27, D26) > 0, "Holiday", TEXT(D26, "dddd"))) -> Holiday | C26: =TEXT(D26,"dddd") -> Monday | D26: 46167 | I26: =IFERROR((G26/H26)*60, "") | P26: =IF(ISBLANK(E26), "", TRANSPOSE(INDIRECT(E26)))
A27: =WEEKNUM(D27,2) -> 22 | B27: =IF(OR(WEEKDAY(D27)=1, WEEKDAY(D27)=7), TEXT(D27, "dddd"), IF(COUNTIF(Reference!$A$13:$A$27, D27) > 0, "Holiday", TEXT(D27, "dddd"))) -> Tuesday | C27: =TEXT(D27,"dddd") -> Tuesday | D27: 46168 | E27: Manual_TPfC | F27: TPfC Phase 3 | G27: 8 | H27: 19 | I27: =IFERROR((G27/H27)*60, "") -> 25.263158 | P27: =IF(ISBLANK(E27), "", TRANSPOSE(INDIRECT(E27))) -> TPfC Phase 3 | Q27: TPfC Phase 4
A28: =WEEKNUM(D28,2) -> 22 | B28: =IF(OR(WEEKDAY(D28)=1, WEEKDAY(D28)=7), TEXT(D28, "dddd"), IF(COUNTIF(Reference!$A$13:$A$27, D28) > 0, "Holiday", TEXT(D28, "dddd"))) -> Wednesday | C28: =TEXT(D28,"dddd") -> Wednesday | D28: 46169 | E28: Manual_TPfC | F28: TPfC Phase 3 | G28: 8 | H28: 17 | I28: =IFERROR((G28/H28)*60, "") -> 28.235294 | P28: =IF(ISBLANK(E28), "", TRANSPOSE(INDIRECT(E28))) -> TPfC Phase 3 | Q28: TPfC Phase 4
A29: =WEEKNUM(D29,2) -> 22 | B29: =IF(OR(WEEKDAY(D29)=1, WEEKDAY(D29)=7), TEXT(D29, "dddd"), IF(COUNTIF(Reference!$A$13:$A$27, D29) > 0, "Holiday", TEXT(D29, "dddd"))) -> Thursday | C29: =TEXT(D29,"dddd") -> Thursday | D29: 46170 | E29: Manual_TPfC | F29: TPfC Phase 3 | G29: 4 | H29: 12 | I29: =IFERROR((G29/H29)*60, "") -> 20 | P29: =IF(ISBLANK(E29), "", TRANSPOSE(INDIRECT(E29))) -> TPfC Phase 3 | Q29: TPfC Phase 4
A30: =WEEKNUM(D30,2) -> 22 | B30: =IF(OR(WEEKDAY(D30)=1, WEEKDAY(D30)=7), TEXT(D30, "dddd"), IF(COUNTIF(Reference!$A$13:$A$27, D30) > 0, "Holiday", TEXT(D30, "dddd"))) -> Friday | C30: =TEXT(D30,"dddd") -> Friday | D30: 46171 | I30: =IFERROR((G30/H30)*60, "") | P30: =IF(ISBLANK(E30), "", TRANSPOSE(INDIRECT(E30)))
A31: =WEEKNUM(D31,2) -> 22 | B31: =IF(OR(WEEKDAY(D31)=1, WEEKDAY(D31)=7), TEXT(D31, "dddd"), IF(COUNTIF(Reference!$A$13:$A$27, D31) > 0, "Holiday", TEXT(D31, "dddd"))) -> Saturday | C31: =TEXT(D31,"dddd") -> Saturday | D31: 46172 | I31: =IFERROR((G31/H31)*60, "") | P31: =IF(ISBLANK(E31), "", TRANSPOSE(INDIRECT(E31)))
A32: =WEEKNUM(D32,2) -> 22 | B32: =IF(OR(WEEKDAY(D32)=1, WEEKDAY(D32)=7), TEXT(D32, "dddd"), IF(COUNTIF(Reference!$A$13:$A$27, D32) > 0, "Holiday", TEXT(D32, "dddd"))) -> Sunday | C32: =TEXT(D32,"dddd") -> Sunday | D32: 46173 | I32: =IFERROR((G32/H32)*60, "") | P32: =IF(ISBLANK(E32), "", TRANSPOSE(INDIRECT(E32)))
A33: =WEEKNUM(D33,2) -> 23 | B33: =IF(OR(WEEKDAY(D33)=1, WEEKDAY(D33)=7), TEXT(D33, "dddd"), IF(COUNTIF(Reference!$A$13:$A$27, D33) > 0, "Holiday", TEXT(D33, "dddd"))) -> Monday | C33: =TEXT(D33,"dddd") -> Monday | D33: 46174 | E33: Manual_TPfC | F33: TPfC Phase 3 | G33: 8 | H33: 18 | I33: =IFERROR((G33/H33)*60, "") -> 26.666667 | P33: =IF(ISBLANK(E33), "", TRANSPOSE(INDIRECT(E33))) -> TPfC Phase 3 | Q33: TPfC Phase 4
A34: =WEEKNUM(D34,2) -> 23 | B34: =IF(OR(WEEKDAY(D34)=1, WEEKDAY(D34)=7), TEXT(D34, "dddd"), IF(COUNTIF(Reference!$A$13:$A$27, D34) > 0, "Holiday", TEXT(D34, "dddd"))) -> Tuesday | C34: =TEXT(D34,"dddd") -> Tuesday | D34: 46175 | E34: Manual_TPfC | F34: TPfC Phase 3 | G34: 4 | H34: 22 | I34: =IFERROR((G34/H34)*60, "") -> 10.909091 | P34: =IF(ISBLANK(E34), "", TRANSPOSE(INDIRECT(E34))) -> TPfC Phase 3 | Q34: TPfC Phase 4
A35: =WEEKNUM(D35,2) -> 23 | B35: =IF(OR(WEEKDAY(D35)=1, WEEKDAY(D35)=7), TEXT(D35, "dddd"), IF(COUNTIF(Reference!$A$13:$A$27, D35) > 0, "Holiday", TEXT(D35, "dddd"))) -> Wednesday | C35: =TEXT(D35,"dddd") -> Wednesday | D35: 46176 | E35: Manual_TPfC | F35: TPfC Phase 3 | G35: 4 | H35: 8 | I35: =IFERROR((G35/H35)*60, "") -> 30 | P35: =IF(ISBLANK(E35), "", TRANSPOSE(INDIRECT(E35))) -> TPfC Phase 3 | Q35: TPfC Phase 4
A36: =WEEKNUM(D36,2) -> 23 | B36: =IF(OR(WEEKDAY(D36)=1, WEEKDAY(D36)=7), TEXT(D36, "dddd"), IF(COUNTIF(Reference!$A$13:$A$27, D36) > 0, "Holiday", TEXT(D36, "dddd"))) -> Holiday | C36: =TEXT(D36,"dddd") -> Thursday | D36: 46177 | I36: =IFERROR((G36/H36)*60, "") | P36: =IF(ISBLANK(E36), "", TRANSPOSE(INDIRECT(E36)))
A37: =WEEKNUM(D37,2) -> 23 | B37: =IF(OR(WEEKDAY(D37)=1, WEEKDAY(D37)=7), TEXT(D37, "dddd"), IF(COUNTIF(Reference!$A$13:$A$27, D37) > 0, "Holiday", TEXT(D37, "dddd"))) -> Friday | C37: =TEXT(D37,"dddd") -> Friday | D37: 46178 | E37: Manual_TPfC | F37: TPfC Phase 3 | G37: 4 | H37: 10 | I37: =IFERROR((G37/H37)*60, "") -> 24 | P37: =IF(ISBLANK(E37), "", TRANSPOSE(INDIRECT(E37))) -> TPfC Phase 3 | Q37: TPfC Phase 4
A38: =WEEKNUM(D38,2) -> 23 | B38: =IF(OR(WEEKDAY(D38)=1, WEEKDAY(D38)=7), TEXT(D38, "dddd"), IF(COUNTIF(Reference!$A$13:$A$27, D38) > 0, "Holiday", TEXT(D38, "dddd"))) -> Saturday | C38: =TEXT(D38,"dddd") -> Saturday | D38: 46179 | I38: =IFERROR((G38/H38)*60, "") | P38: =IF(ISBLANK(E38), "", TRANSPOSE(INDIRECT(E38)))
A39: =WEEKNUM(D39,2) -> 23 | B39: =IF(OR(WEEKDAY(D39)=1, WEEKDAY(D39)=7), TEXT(D39, "dddd"), IF(COUNTIF(Reference!$A$13:$A$27, D39) > 0, "Holiday", TEXT(D39, "dddd"))) -> Sunday | C39: =TEXT(D39,"dddd") -> Sunday | D39: 46180 | I39: =IFERROR((G39/H39)*60, "") | P39: =IF(ISBLANK(E39), "", TRANSPOSE(INDIRECT(E39)))
A40: =WEEKNUM(D40,2) -> 24 | B40: =IF(OR(WEEKDAY(D40)=1, WEEKDAY(D40)=7), TEXT(D40, "dddd"), IF(COUNTIF(Reference!$A$13:$A$27, D40) > 0, "Holiday", TEXT(D40, "dddd"))) -> Monday | C40: =TEXT(D40,"dddd") -> Monday | D40: 46181 | E40: Manual_TPfC | F40: TPfC Phase 3 | G40: 8 | H40: 10 | I40: =IFERROR((G40/H40)*60, "") -> 48 | P40: =IF(ISBLANK(E40), "", TRANSPOSE(INDIRECT(E40))) -> TPfC Phase 3 | Q40: TPfC Phase 4
...

Sheet Javeria
A1: KW | B1: Holiday OR Weekend | C1: Day | D1: Date | E1: Project | F1: Task | G1: Duration (Hrs) | H1: # of Signals | I1: Time per Signal (mins) | J1: Notes
A2: =WEEKNUM(D2,2) -> 18 | B2: =IF(OR(WEEKDAY(D2)=1, WEEKDAY(D2)=7), TEXT(D2, "dddd"), IF(COUNTIF(Reference!$A$13:$A$27, D2) > 0, "Holiday", TEXT(D2, "dddd"))) -> Holiday | C2: =TEXT(D2,"dddd") -> Friday | D2: 46143 | O2: =IF(ISBLANK(E2), "", TRANSPOSE(INDIRECT(E2)))
A3: =WEEKNUM(D3,2) -> 18 | B3: =IF(OR(WEEKDAY(D3)=1, WEEKDAY(D3)=7), TEXT(D3, "dddd"), IF(COUNTIF(Reference!$A$13:$A$27, D3) > 0, "Holiday", TEXT(D3, "dddd"))) -> Saturday | C3: =TEXT(D3,"dddd") -> Saturday | D3: 46144 | I3: =IFERROR((G3/H3)*60, "") | O3: =IF(ISBLANK(E3), "", TRANSPOSE(INDIRECT(E3)))
A4: =WEEKNUM(D4,2) -> 18 | B4: =IF(OR(WEEKDAY(D4)=1, WEEKDAY(D4)=7), TEXT(D4, "dddd"), IF(COUNTIF(Reference!$A$13:$A$27, D4) > 0, "Holiday", TEXT(D4, "dddd"))) -> Sunday | C4: =TEXT(D4,"dddd") -> Sunday | D4: 46145 | I4: =IFERROR((G4/H4)*60, "") | O4: =IF(ISBLANK(E4), "", TRANSPOSE(INDIRECT(E4)))
A5: =WEEKNUM(D5,2) -> 19 | B5: =IF(OR(WEEKDAY(D5)=1, WEEKDAY(D5)=7), TEXT(D5, "dddd"), IF(COUNTIF(Reference!$A$13:$A$27, D5) > 0, "Holiday", TEXT(D5, "dddd"))) -> Monday | C5: =TEXT(D5,"dddd") -> Monday | D5: 46146 | I5: =IFERROR((G5/H5)*60, "") | O5: =IF(ISBLANK(E5), "", TRANSPOSE(INDIRECT(E5)))
A6: =WEEKNUM(D6,2) -> 19 | B6: =IF(OR(WEEKDAY(D6)=1, WEEKDAY(D6)=7), TEXT(D6, "dddd"), IF(COUNTIF(Reference!$A$13:$A$27, D6) > 0, "Holiday", TEXT(D6, "dddd"))) -> Tuesday | C6: =TEXT(D6,"dddd") -> Tuesday | D6: 46147 | E6: Manual_TPfC | F6: TPfC Phase 3 | G6: 7.5 | H6: 12 | I6: =IFERROR((G6/H6)*60, "") -> 37.5 | O6: =IF(ISBLANK(E6), "", TRANSPOSE(INDIRECT(E6))) -> TPfC Phase 3 | P6: TPfC Phase 4
A7: =WEEKNUM(D7,2) -> 19 | B7: =IF(OR(WEEKDAY(D7)=1, WEEKDAY(D7)=7), TEXT(D7, "dddd"), IF(COUNTIF(Reference!$A$13:$A$27, D7) > 0, "Holiday", TEXT(D7, "dddd"))) -> Wednesday | C7: =TEXT(D7,"dddd") -> Wednesday | D7: 46148 | E7: Manual_TPfC | F7: TPfC Phase 3 | G7: 6.5 | H7: 10 | I7: =IFERROR((G7/H7)*60, "") -> 39 | O7: =IF(ISBLANK(E7), "", TRANSPOSE(INDIRECT(E7))) -> TPfC Phase 3 | P7: TPfC Phase 4
A8: =WEEKNUM(D8,2) -> 19 | B8: =IF(OR(WEEKDAY(D8)=1, WEEKDAY(D8)=7), TEXT(D8, "dddd"), IF(COUNTIF(Reference!$A$13:$A$27, D8) > 0, "Holiday", TEXT(D8, "dddd"))) -> Thursday | C8: =TEXT(D8,"dddd") -> Thursday | D8: 46149 | E8: Manual_TPfC | F8: TPfC Phase 3 | G8: 6 | H8: 10 | I8: =IFERROR((G8/H8)*60, "") -> 36 | O8: =IF(ISBLANK(E8), "", TRANSPOSE(INDIRECT(E8))) -> TPfC Phase 3 | P8: TPfC Phase 4
A9: =WEEKNUM(D9,2) -> 19 | B9: =IF(OR(WEEKDAY(D9)=1, WEEKDAY(D9)=7), TEXT(D9, "dddd"), IF(COUNTIF(Reference!$A$13:$A$27, D9) > 0, "Holiday", TEXT(D9, "dddd"))) -> Friday | C9: =TEXT(D9,"dddd") -> Friday | D9: 46150 | I9: =IFERROR((G9/H9)*60, "") | O9: =IF(ISBLANK(E9), "", TRANSPOSE(INDIRECT(E9)))
A10: =WEEKNUM(D10,2) -> 19 | B10: =IF(OR(WEEKDAY(D10)=1, WEEKDAY(D10)=7), TEXT(D10, "dddd"), IF(COUNTIF(Reference!$A$13:$A$27, D10) > 0, "Holiday", TEXT(D10, "dddd"))) -> Saturday | C10: =TEXT(D10,"dddd") -> Saturday | D10: 46151 | I10: =IFERROR((G10/H10)*60, "") | O10: =IF(ISBLANK(E10), "", TRANSPOSE(INDIRECT(E10)))
A11: =WEEKNUM(D11,2) -> 19 | B11: =IF(OR(WEEKDAY(D11)=1, WEEKDAY(D11)=7), TEXT(D11, "dddd"), IF(COUNTIF(Reference!$A$13:$A$27, D11) > 0, "Holiday", TEXT(D11, "dddd"))) -> Sunday | C11: =TEXT(D11,"dddd") -> Sunday | D11: 46152 | I11: =IFERROR((G11/H11)*60, "") | O11: =IF(ISBLANK(E11), "", TRANSPOSE(INDIRECT(E11)))
A12: =WEEKNUM(D12,2) -> 20 | B12: =IF(OR(WEEKDAY(D12)=1, WEEKDAY(D12)=7), TEXT(D12, "dddd"), IF(COUNTIF(Reference!$A$13:$A$27, D12) > 0, "Holiday", TEXT(D12, "dddd"))) -> Monday | C12: =TEXT(D12,"dddd") -> Monday | D12: 46153 | I12: =IFERROR((G12/H12)*60, "") | O12: =IF(ISBLANK(E12), "", TRANSPOSE(INDIRECT(E12)))
A13: =WEEKNUM(D13,2) -> 20 | B13: =IF(OR(WEEKDAY(D13)=1, WEEKDAY(D13)=7), TEXT(D13, "dddd"), IF(COUNTIF(Reference!$A$13:$A$27, D13) > 0, "Holiday", TEXT(D13, "dddd"))) -> Tuesday | C13: =TEXT(D13,"dddd") -> Tuesday | D13: 46154 | I13: =IFERROR((G13/H13)*60, "") | O13: =IF(ISBLANK(E13), "", TRANSPOSE(INDIRECT(E13)))
A14: =WEEKNUM(D14,2) -> 20 | B14: =IF(OR(WEEKDAY(D14)=1, WEEKDAY(D14)=7), TEXT(D14, "dddd"), IF(COUNTIF(Reference!$A$13:$A$27, D14) > 0, "Holiday", TEXT(D14, "dddd"))) -> Wednesday | C14: =TEXT(D14,"dddd") -> Wednesday | D14: 46155 | I14: =IFERROR((G14/H14)*60, "") | O14: =IF(ISBLANK(E14), "", TRANSPOSE(INDIRECT(E14)))
A15: =WEEKNUM(D15,2) -> 20 | B15: =IF(OR(WEEKDAY(D15)=1, WEEKDAY(D15)=7), TEXT(D15, "dddd"), IF(COUNTIF(Reference!$A$13:$A$27, D15) > 0, "Holiday", TEXT(D15, "dddd"))) -> Holiday | C15: =TEXT(D15,"dddd") -> Thursday | D15: 46156 | I15: =IFERROR((G15/H15)*60, "") | O15: =IF(ISBLANK(E15), "", TRANSPOSE(INDIRECT(E15)))
A16: =WEEKNUM(D16,2) -> 20 | B16: =IF(OR(WEEKDAY(D16)=1, WEEKDAY(D16)=7), TEXT(D16, "dddd"), IF(COUNTIF(Reference!$A$13:$A$27, D16) > 0, "Holiday", TEXT(D16, "dddd"))) -> Friday | C16: =TEXT(D16,"dddd") -> Friday | D16: 46157 | I16: =IFERROR((G16/H16)*60, "") | O16: =IF(ISBLANK(E16), "", TRANSPOSE(INDIRECT(E16)))
A17: =WEEKNUM(D17,2) -> 20 | B17: =IF(OR(WEEKDAY(D17)=1, WEEKDAY(D17)=7), TEXT(D17, "dddd"), IF(COUNTIF(Reference!$A$13:$A$27, D17) > 0, "Holiday", TEXT(D17, "dddd"))) -> Saturday | C17: =TEXT(D17,"dddd") -> Saturday | D17: 46158 | I17: =IFERROR((G17/H17)*60, "") | O17: =IF(ISBLANK(E17), "", TRANSPOSE(INDIRECT(E17)))
A18: =WEEKNUM(D18,2) -> 20 | B18: =IF(OR(WEEKDAY(D18)=1, WEEKDAY(D18)=7), TEXT(D18, "dddd"), IF(COUNTIF(Reference!$A$13:$A$27, D18) > 0, "Holiday", TEXT(D18, "dddd"))) -> Sunday | C18: =TEXT(D18,"dddd") -> Sunday | D18: 46159 | I18: =IFERROR((G18/H18)*60, "") | O18: =IF(ISBLANK(E18), "", TRANSPOSE(INDIRECT(E18)))
A19: =WEEKNUM(D19,2) -> 21 | B19: =IF(OR(WEEKDAY(D19)=1, WEEKDAY(D19)=7), TEXT(D19, "dddd"), IF(COUNTIF(Reference!$A$13:$A$27, D19) > 0, "Holiday", TEXT(D19, "dddd"))) -> Monday | C19: =TEXT(D19,"dddd") -> Monday | D19: 46160 | I19: =IFERROR((G19/H19)*60, "") | O19: =IF(ISBLANK(E19), "", TRANSPOSE(INDIRECT(E19)))
A20: =WEEKNUM(D20,2) -> 21 | B20: =IF(OR(WEEKDAY(D20)=1, WEEKDAY(D20)=7), TEXT(D20, "dddd"), IF(COUNTIF(Reference!$A$13:$A$27, D20) > 0, "Holiday", TEXT(D20, "dddd"))) -> Tuesday | C20: =TEXT(D20,"dddd") -> Tuesday | D20: 46161 | I20: =IFERROR((G20/H20)*60, "") | O20: =IF(ISBLANK(E20), "", TRANSPOSE(INDIRECT(E20)))
A21: =WEEKNUM(D21,2) -> 21 | B21: =IF(OR(WEEKDAY(D21)=1, WEEKDAY(D21)=7), TEXT(D21, "dddd"), IF(COUNTIF(Reference!$A$13:$A$27, D21) > 0, "Holiday", TEXT(D21, "dddd"))) -> Wednesday | C21: =TEXT(D21,"dddd") -> Wednesday | D21: 46162 | E21: Manual_TPfC | F21: TPfC Phase 3 | G21: 7.5 | H21: 20 | I21: =IFERROR((G21/H21)*60, "") -> 22.5 | O21: =IF(ISBLANK(E21), "", TRANSPOSE(INDIRECT(E21))) -> TPfC Phase 3 | P21: TPfC Phase 4
A22: =WEEKNUM(D22,2) -> 21 | B22: =IF(OR(WEEKDAY(D22)=1, WEEKDAY(D22)=7), TEXT(D22, "dddd"), IF(COUNTIF(Reference!$A$13:$A$27, D22) > 0, "Holiday", TEXT(D22, "dddd"))) -> Thursday | C22: =TEXT(D22,"dddd") -> Thursday | D22: 46163 | E22: Manual_TPfC | F22: TPfC Phase 3 | G22: 4.5 | H22: 10 | I22: =IFERROR((G22/H22)*60, "") -> 27 | O22: =IF(ISBLANK(E22), "", TRANSPOSE(INDIRECT(E22))) -> TPfC Phase 3 | P22: TPfC Phase 4
A23: =WEEKNUM(D23,2) -> 21 | B23: =IF(OR(WEEKDAY(D23)=1, WEEKDAY(D23)=7), TEXT(D23, "dddd"), IF(COUNTIF(Reference!$A$13:$A$27, D23) > 0, "Holiday", TEXT(D23, "dddd"))) -> Friday | C23: =TEXT(D23,"dddd") -> Friday | D23: 46164 | E23: Manual_TPfC | F23: TPfC Phase 3 | G23: 8 | H23: 10 | I23: =IFERROR((G23/H23)*60, "") -> 48 | O23: =IF(ISBLANK(E23), "", TRANSPOSE(INDIRECT(E23))) -> TPfC Phase 3 | P23: TPfC Phase 4
A24: =WEEKNUM(D24,2) -> 21 | B24: =IF(OR(WEEKDAY(D24)=1, WEEKDAY(D24)=7), TEXT(D24, "dddd"), IF(COUNTIF(Reference!$A$13:$A$27, D24) > 0, "Holiday", TEXT(D24, "dddd"))) -> Saturday | C24: =TEXT(D24,"dddd") -> Saturday | D24: 46165 | I24: =IFERROR((G24/H24)*60, "") | O24: =IF(ISBLANK(E24), "", TRANSPOSE(INDIRECT(E24)))
A25: =WEEKNUM(D25,2) -> 21 | B25: =IF(OR(WEEKDAY(D25)=1, WEEKDAY(D25)=7), TEXT(D25, "dddd"), IF(COUNTIF(Reference!$A$13:$A$27, D25) > 0, "Holiday", TEXT(D25, "dddd"))) -> Sunday | C25: =TEXT(D25,"dddd") -> Sunday | D25: 46166 | I25: =IFERROR((G25/H25)*60, "") | O25: =IF(ISBLANK(E25), "", TRANSPOSE(INDIRECT(E25)))
A26: =WEEKNUM(D26,2) -> 22 | B26: =IF(OR(WEEKDAY(D26)=1, WEEKDAY(D26)=7), TEXT(D26, "dddd"), IF(COUNTIF(Reference!$A$13:$A$27, D26) > 0, "Holiday", TEXT(D26, "dddd"))) -> Holiday | C26: =TEXT(D26,"dddd") -> Monday | D26: 46167 | I26: =IFERROR((G26/H26)*60, "") | O26: =IF(ISBLANK(E26), "", TRANSPOSE(INDIRECT(E26)))
A27: =WEEKNUM(D27,2) -> 22 | B27: =IF(OR(WEEKDAY(D27)=1, WEEKDAY(D27)=7), TEXT(D27, "dddd"), IF(COUNTIF(Reference!$A$13:$A$27, D27) > 0, "Holiday", TEXT(D27, "dddd"))) -> Tuesday | C27: =TEXT(D27,"dddd") -> Tuesday | D27: 46168 | E27: Manual_TPfC | F27: TPfC Phase 3 | G27: 7.5 | H27: 14 | I27: =IFERROR((G27/H27)*60, "") -> 32.142857 | O27: =IF(ISBLANK(E27), "", TRANSPOSE(INDIRECT(E27))) -> TPfC Phase 3 | P27: TPfC Phase 4
A28: =WEEKNUM(D28,2) -> 22 | B28: =IF(OR(WEEKDAY(D28)=1, WEEKDAY(D28)=7), TEXT(D28, "dddd"), IF(COUNTIF(Reference!$A$13:$A$27, D28) > 0, "Holiday", TEXT(D28, "dddd"))) -> Wednesday | C28: =TEXT(D28,"dddd") -> Wednesday | D28: 46169 | E28: Manual_TPfC | F28: TPfC Phase 3 | G28: 7.5 | H28: 13 | I28: =IFERROR((G28/H28)*60, "") -> 34.615385 | O28: =IF(ISBLANK(E28), "", TRANSPOSE(INDIRECT(E28))) -> TPfC Phase 3 | P28: TPfC Phase 4
A29: =WEEKNUM(D29,2) -> 22 | B29: =IF(OR(WEEKDAY(D29)=1, WEEKDAY(D29)=7), TEXT(D29, "dddd"), IF(COUNTIF(Reference!$A$13:$A$27, D29) > 0, "Holiday", TEXT(D29, "dddd"))) -> Thursday | C29: =TEXT(D29,"dddd") -> Thursday | D29: 46170 | E29: Manual_TPfC | F29: TPfC Phase 3 | G29: 5 | H29: 10 | I29: =IFERROR((G29/H29)*60, "") -> 30 | O29: =IF(ISBLANK(E29), "", TRANSPOSE(INDIRECT(E29))) -> TPfC Phase 3 | P29: TPfC Phase 4
A30: =WEEKNUM(D30,2) -> 22 | B30: =IF(OR(WEEKDAY(D30)=1, WEEKDAY(D30)=7), TEXT(D30, "dddd"), IF(COUNTIF(Reference!$A$13:$A$27, D30) > 0, "Holiday", TEXT(D30, "dddd"))) -> Friday | C30: =TEXT(D30,"dddd") -> Friday | D30: 46171 | I30: =IFERROR((G30/H30)*60, "") | O30: =IF(ISBLANK(E30), "", TRANSPOSE(INDIRECT(E30)))
A31: =WEEKNUM(D31,2) -> 22 | B31: =IF(OR(WEEKDAY(D31)=1, WEEKDAY(D31)=7), TEXT(D31, "dddd"), IF(COUNTIF(Reference!$A$13:$A$27, D31) > 0, "Holiday", TEXT(D31, "dddd"))) -> Saturday | C31: =TEXT(D31,"dddd") -> Saturday | D31: 46172 | I31: =IFERROR((G31/H31)*60, "") | O31: =IF(ISBLANK(E31), "", TRANSPOSE(INDIRECT(E31)))
A32: =WEEKNUM(D32,2) -> 22 | B32: =IF(OR(WEEKDAY(D32)=1, WEEKDAY(D32)=7), TEXT(D32, "dddd"), IF(COUNTIF(Reference!$A$13:$A$27, D32) > 0, "Holiday", TEXT(D32, "dddd"))) -> Sunday | C32: =TEXT(D32,"dddd") -> Sunday | D32: 46173 | I32: =IFERROR((G32/H32)*60, "") | O32: =IF(ISBLANK(E32), "", TRANSPOSE(INDIRECT(E32)))
A33: =WEEKNUM(D33,2) -> 23 | B33: =IF(OR(WEEKDAY(D33)=1, WEEKDAY(D33)=7), TEXT(D33, "dddd"), IF(COUNTIF(Reference!$A$13:$A$27, D33) > 0, "Holiday", TEXT(D33, "dddd"))) -> Monday | C33: =TEXT(D33,"dddd") -> Monday | D33: 46174 | E33: Manual_TPfC | F33: TPfC Phase 3 | G33: 7.5 | H33: 15 | I33: =IFERROR((G33/H33)*60, "") -> 30 | O33: =IF(ISBLANK(E33), "", TRANSPOSE(INDIRECT(E33))) -> TPfC Phase 3 | P33: TPfC Phase 4
A34: =WEEKNUM(D34,2) -> 23 | B34: =IF(OR(WEEKDAY(D34)=1, WEEKDAY(D34)=7), TEXT(D34, "dddd"), IF(COUNTIF(Reference!$A$13:$A$27, D34) > 0, "Holiday", TEXT(D34, "dddd"))) -> Tuesday | C34: =TEXT(D34,"dddd") -> Tuesday | D34: 46175 | E34: Manual_TPfC | F34: TPfC Phase 3 | G34: 4 | H34: 8 | I34: =IFERROR((G34/H34)*60, "") -> 30 | O34: =IF(ISBLANK(E34), "", TRANSPOSE(INDIRECT(E34))) -> TPfC Phase 3 | P34: TPfC Phase 4
A35: =WEEKNUM(D35,2) -> 23 | B35: =IF(OR(WEEKDAY(D35)=1, WEEKDAY(D35)=7), TEXT(D35, "dddd"), IF(COUNTIF(Reference!$A$13:$A$27, D35) > 0, "Holiday", TEXT(D35, "dddd"))) -> Wednesday | C35: =TEXT(D35,"dddd") -> Wednesday | D35: 46176 | E35: Manual_TPfC | F35: TPfC Phase 3 | G35: 8.5 | H35: 17 | I35: =IFERROR((G35/H35)*60, "") -> 30 | O35: =IF(ISBLANK(E35), "", TRANSPOSE(INDIRECT(E35))) -> TPfC Phase 3 | P35: TPfC Phase 4
A36: =WEEKNUM(D36,2) -> 23 | B36: =IF(OR(WEEKDAY(D36)=1, WEEKDAY(D36)=7), TEXT(D36, "dddd"), IF(COUNTIF(Reference!$A$13:$A$27, D36) > 0, "Holiday", TEXT(D36, "dddd"))) -> Holiday | C36: =TEXT(D36,"dddd") -> Thursday | D36: 46177 | I36: =IFERROR((G36/H36)*60, "") | O36: =IF(ISBLANK(E36), "", TRANSPOSE(INDIRECT(E36)))
A37: =WEEKNUM(D37,2) -> 23 | B37: =IF(OR(WEEKDAY(D37)=1, WEEKDAY(D37)=7), TEXT(D37, "dddd"), IF(COUNTIF(Reference!$A$13:$A$27, D37) > 0, "Holiday", TEXT(D37, "dddd"))) -> Friday | C37: =TEXT(D37,"dddd") -> Friday | D37: 46178 | I37: =IFERROR((G37/H37)*60, "") | O37: =IF(ISBLANK(E37), "", TRANSPOSE(INDIRECT(E37)))
A38: =WEEKNUM(D38,2) -> 23 | B38: =IF(OR(WEEKDAY(D38)=1, WEEKDAY(D38)=7), TEXT(D38, "dddd"), IF(COUNTIF(Reference!$A$13:$A$27, D38) > 0, "Holiday", TEXT(D38, "dddd"))) -> Saturday | C38: =TEXT(D38,"dddd") -> Saturday | D38: 46179 | I38: =IFERROR((G38/H38)*60, "") | O38: =IF(ISBLANK(E38), "", TRANSPOSE(INDIRECT(E38)))
A39: =WEEKNUM(D39,2) -> 23 | B39: =IF(OR(WEEKDAY(D39)=1, WEEKDAY(D39)=7), TEXT(D39, "dddd"), IF(COUNTIF(Reference!$A$13:$A$27, D39) > 0, "Holiday", TEXT(D39, "dddd"))) -> Sunday | C39: =TEXT(D39,"dddd") -> Sunday | D39: 46180 | I39: =IFERROR((G39/H39)*60, "") | O39: =IF(ISBLANK(E39), "", TRANSPOSE(INDIRECT(E39)))
A40: =WEEKNUM(D40,2) -> 24 | B40: =IF(OR(WEEKDAY(D40)=1, WEEKDAY(D40)=7), TEXT(D40, "dddd"), IF(COUNTIF(Reference!$A$13:$A$27, D40) > 0, "Holiday", TEXT(D40, "dddd"))) -> Monday | C40: =TEXT(D40,"dddd") -> Monday | D40: 46181 | I40: =IFERROR((G40/H40)*60, "") | O40: =IF(ISBLANK(E40), "", TRANSPOSE(INDIRECT(E40)))
...

Sheet Fasih
A1: KW | B1: Holiday OR Weekend | C1: Day | D1: Date | E1: Project | F1: Task | G1: Duration (Hrs) | H1: # of Signals | I1: Time per Signal (mins) | J1: Notes
A2: =WEEKNUM(D2,2) -> 18 | B2: =IF(OR(WEEKDAY(D2)=1, WEEKDAY(D2)=7), TEXT(D2, "dddd"), IF(COUNTIF(Reference!$A$13:$A$27, D2) > 0, "Holiday", TEXT(D2, "dddd"))) -> Holiday | C2: =TEXT(D2,"dddd") -> Friday | D2: 46143 | P2: =IF(ISBLANK(E2), "", TRANSPOSE(INDIRECT(E2)))
A3: =WEEKNUM(D3,2) -> 18 | B3: =IF(OR(WEEKDAY(D3)=1, WEEKDAY(D3)=7), TEXT(D3, "dddd"), IF(COUNTIF(Reference!$A$13:$A$27, D3) > 0, "Holiday", TEXT(D3, "dddd"))) -> Saturday | C3: =TEXT(D3,"dddd") -> Saturday | D3: 46144 | I3: =IFERROR((G3/H3)*60, "") | P3: =IF(ISBLANK(E3), "", TRANSPOSE(INDIRECT(E3)))
A4: =WEEKNUM(D4,2) -> 18 | B4: =IF(OR(WEEKDAY(D4)=1, WEEKDAY(D4)=7), TEXT(D4, "dddd"), IF(COUNTIF(Reference!$A$13:$A$27, D4) > 0, "Holiday", TEXT(D4, "dddd"))) -> Sunday | C4: =TEXT(D4,"dddd") -> Sunday | D4: 46145 | I4: =IFERROR((G4/H4)*60, "") | P4: =IF(ISBLANK(E4), "", TRANSPOSE(INDIRECT(E4)))
A5: =WEEKNUM(D5,2) -> 19 | B5: =IF(OR(WEEKDAY(D5)=1, WEEKDAY(D5)=7), TEXT(D5, "dddd"), IF(COUNTIF(Reference!$A$13:$A$27, D5) > 0, "Holiday", TEXT(D5, "dddd"))) -> Monday | C5: =TEXT(D5,"dddd") -> Monday | D5: 46146 | E5: Topology_Coding | F5: TPfC Phase 3 | G5: 8 | I5: =IFERROR((G5/H5)*60, "") | P5: =IF(ISBLANK(E5), "", TRANSPOSE(INDIRECT(E5))) -> Netherlands | Q5: Norway | R5: Switzerland | S5: UK
A6: =WEEKNUM(D6,2) -> 19 | B6: =IF(OR(WEEKDAY(D6)=1, WEEKDAY(D6)=7), TEXT(D6, "dddd"), IF(COUNTIF(Reference!$A$13:$A$27, D6) > 0, "Holiday", TEXT(D6, "dddd"))) -> Tuesday | C6: =TEXT(D6,"dddd") -> Tuesday | D6: 46147 | E6: Topology_Coding | F6: TPfC Phase 3 | G6: 8 | I6: =IFERROR((G6/H6)*60, "") | P6: =IF(ISBLANK(E6), "", TRANSPOSE(INDIRECT(E6))) -> Netherlands | Q6: Norway | R6: Switzerland | S6: UK
A7: =WEEKNUM(D7,2) -> 19 | B7: =IF(OR(WEEKDAY(D7)=1, WEEKDAY(D7)=7), TEXT(D7, "dddd"), IF(COUNTIF(Reference!$A$13:$A$27, D7) > 0, "Holiday", TEXT(D7, "dddd"))) -> Wednesday | C7: =TEXT(D7,"dddd") -> Wednesday | D7: 46148 | E7: Topology_Coding | F7: TPfC Phase 3 | G7: 4 | I7: =IFERROR((G7/H7)*60, "") | P7: =IF(ISBLANK(E7), "", TRANSPOSE(INDIRECT(E7))) -> Netherlands | Q7: Norway | R7: Switzerland | S7: UK
A8: =WEEKNUM(D8,2) -> 19 | B8: =IF(OR(WEEKDAY(D8)=1, WEEKDAY(D8)=7), TEXT(D8, "dddd"), IF(COUNTIF(Reference!$A$13:$A$27, D8) > 0, "Holiday", TEXT(D8, "dddd"))) -> Thursday | C8: =TEXT(D8,"dddd") -> Thursday | D8: 46149 | I8: =IFERROR((G8/H8)*60, "") | P8: =IF(ISBLANK(E8), "", TRANSPOSE(INDIRECT(E8)))
A9: =WEEKNUM(D9,2) -> 19 | B9: =IF(OR(WEEKDAY(D9)=1, WEEKDAY(D9)=7), TEXT(D9, "dddd"), IF(COUNTIF(Reference!$A$13:$A$27, D9) > 0, "Holiday", TEXT(D9, "dddd"))) -> Friday | C9: =TEXT(D9,"dddd") -> Friday | D9: 46150 | I9: =IFERROR((G9/H9)*60, "") | P9: =IF(ISBLANK(E9), "", TRANSPOSE(INDIRECT(E9)))
A10: =WEEKNUM(D10,2) -> 19 | B10: =IF(OR(WEEKDAY(D10)=1, WEEKDAY(D10)=7), TEXT(D10, "dddd"), IF(COUNTIF(Reference!$A$13:$A$27, D10) > 0, "Holiday", TEXT(D10, "dddd"))) -> Saturday | C10: =TEXT(D10,"dddd") -> Saturday | D10: 46151 | I10: =IFERROR((G10/H10)*60, "") | P10: =IF(ISBLANK(E10), "", TRANSPOSE(INDIRECT(E10)))
A11: =WEEKNUM(D11,2) -> 19 | B11: =IF(OR(WEEKDAY(D11)=1, WEEKDAY(D11)=7), TEXT(D11, "dddd"), IF(COUNTIF(Reference!$A$13:$A$27, D11) > 0, "Holiday", TEXT(D11, "dddd"))) -> Sunday | C11: =TEXT(D11,"dddd") -> Sunday | D11: 46152 | I11: =IFERROR((G11/H11)*60, "") | P11: =IF(ISBLANK(E11), "", TRANSPOSE(INDIRECT(E11)))
A12: =WEEKNUM(D12,2) -> 20 | B12: =IF(OR(WEEKDAY(D12)=1, WEEKDAY(D12)=7), TEXT(D12, "dddd"), IF(COUNTIF(Reference!$A$13:$A$27, D12) > 0, "Holiday", TEXT(D12, "dddd"))) -> Monday | C12: =TEXT(D12,"dddd") -> Monday | D12: 46153 | E12: Topology_Coding | F12: UK | G12: 6 | I12: =IFERROR((G12/H12)*60, "") | P12: =IF(ISBLANK(E12), "", TRANSPOSE(INDIRECT(E12))) -> Netherlands | Q12: Norway | R12: Switzerland | S12: UK
A13: =WEEKNUM(D13,2) -> 20 | B13: =IF(OR(WEEKDAY(D13)=1, WEEKDAY(D13)=7), TEXT(D13, "dddd"), IF(COUNTIF(Reference!$A$13:$A$27, D13) > 0, "Holiday", TEXT(D13, "dddd"))) -> Tuesday | C13: =TEXT(D13,"dddd") -> Tuesday | D13: 46154 | I13: =IFERROR((G13/H13)*60, "") | P13: =IF(ISBLANK(E13), "", TRANSPOSE(INDIRECT(E13)))
A14: =WEEKNUM(D14,2) -> 20 | B14: =IF(OR(WEEKDAY(D14)=1, WEEKDAY(D14)=7), TEXT(D14, "dddd"), IF(COUNTIF(Reference!$A$13:$A$27, D14) > 0, "Holiday", TEXT(D14, "dddd"))) -> Wednesday | C14: =TEXT(D14,"dddd") -> Wednesday | D14: 46155 | E14: Field_Testing | F14: TPfC - Test Suite | G14: 9 | I14: =IFERROR((G14/H14)*60, "") | P14: =IF(ISBLANK(E14), "", TRANSPOSE(INDIRECT(E14))) -> TPfC - Test Suite
A15: =WEEKNUM(D15,2) -> 20 | B15: =IF(OR(WEEKDAY(D15)=1, WEEKDAY(D15)=7), TEXT(D15, "dddd"), IF(COUNTIF(Reference!$A$13:$A$27, D15) > 0, "Holiday", TEXT(D15, "dddd"))) -> Holiday | C15: =TEXT(D15,"dddd") -> Thursday | D15: 46156 | I15: =IFERROR((G15/H15)*60, "") | P15: =IF(ISBLANK(E15), "", TRANSPOSE(INDIRECT(E15)))
A16: =WEEKNUM(D16,2) -> 20 | B16: =IF(OR(WEEKDAY(D16)=1, WEEKDAY(D16)=7), TEXT(D16, "dddd"), IF(COUNTIF(Reference!$A$13:$A$27, D16) > 0, "Holiday", TEXT(D16, "dddd"))) -> Friday | C16: =TEXT(D16,"dddd") -> Friday | D16: 46157 | I16: =IFERROR((G16/H16)*60, "") | P16: =IF(ISBLANK(E16), "", TRANSPOSE(INDIRECT(E16)))
A17: =WEEKNUM(D17,2) -> 20 | B17: =IF(OR(WEEKDAY(D17)=1, WEEKDAY(D17)=7), TEXT(D17, "dddd"), IF(COUNTIF(Reference!$A$13:$A$27, D17) > 0, "Holiday", TEXT(D17, "dddd"))) -> Saturday | C17: =TEXT(D17,"dddd") -> Saturday | D17: 46158 | E17: Topology_Coding | F17: Switzerland | G17: 3 | I17: =IFERROR((G17/H17)*60, "") | P17: =IF(ISBLANK(E17), "", TRANSPOSE(INDIRECT(E17))) -> Netherlands | Q17: Norway | R17: Switzerland | S17: UK
A18: =WEEKNUM(D18,2) -> 20 | B18: =IF(OR(WEEKDAY(D18)=1, WEEKDAY(D18)=7), TEXT(D18, "dddd"), IF(COUNTIF(Reference!$A$13:$A$27, D18) > 0, "Holiday", TEXT(D18, "dddd"))) -> Sunday | C18: =TEXT(D18,"dddd") -> Sunday | D18: 46159 | I18: =IFERROR((G18/H18)*60, "") | P18: =IF(ISBLANK(E18), "", TRANSPOSE(INDIRECT(E18)))
A19: =WEEKNUM(D19,2) -> 21 | B19: =IF(OR(WEEKDAY(D19)=1, WEEKDAY(D19)=7), TEXT(D19, "dddd"), IF(COUNTIF(Reference!$A$13:$A$27, D19) > 0, "Holiday", TEXT(D19, "dddd"))) -> Monday | C19: =TEXT(D19,"dddd") -> Monday | D19: 46160 | E19: Topology_Coding | F19: UK | G19: 8 | I19: =IFERROR((G19/H19)*60, "") | P19: =IF(ISBLANK(E19), "", TRANSPOSE(INDIRECT(E19))) -> Netherlands | Q19: Norway | R19: Switzerland | S19: UK
A20: =WEEKNUM(D20,2) -> 21 | B20: =IF(OR(WEEKDAY(D20)=1, WEEKDAY(D20)=7), TEXT(D20, "dddd"), IF(COUNTIF(Reference!$A$13:$A$27, D20) > 0, "Holiday", TEXT(D20, "dddd"))) -> Tuesday | C20: =TEXT(D20,"dddd") -> Tuesday | D20: 46161 | E20: Topology_Coding | F20: Switzerland | G20: 8 | I20: =IFERROR((G20/H20)*60, "") | P20: =IF(ISBLANK(E20), "", TRANSPOSE(INDIRECT(E20))) -> Netherlands | Q20: Norway | R20: Switzerland | S20: UK
A21: =WEEKNUM(D21,2) -> 21 | B21: =IF(OR(WEEKDAY(D21)=1, WEEKDAY(D21)=7), TEXT(D21, "dddd"), IF(COUNTIF(Reference!$A$13:$A$27, D21) > 0, "Holiday", TEXT(D21, "dddd"))) -> Wednesday | C21: =TEXT(D21,"dddd") -> Wednesday | D21: 46162 | E21: Topology_Coding | F21: Switzerland | G21: 4 | I21: =IFERROR((G21/H21)*60, "") | P21: =IF(ISBLANK(E21), "", TRANSPOSE(INDIRECT(E21))) -> Netherlands | Q21: Norway | R21: Switzerland | S21: UK
A22: =WEEKNUM(D22,2) -> 21 | B22: =IF(OR(WEEKDAY(D22)=1, WEEKDAY(D22)=7), TEXT(D22, "dddd"), IF(COUNTIF(Reference!$A$13:$A$27, D22) > 0, "Holiday", TEXT(D22, "dddd"))) -> Thursday | C22: =TEXT(D22,"dddd") -> Thursday | D22: 46163 | I22: =IFERROR((G22/H22)*60, "") | P22: =IF(ISBLANK(E22), "", TRANSPOSE(INDIRECT(E22)))
A23: =WEEKNUM(D23,2) -> 21 | B23: =IF(OR(WEEKDAY(D23)=1, WEEKDAY(D23)=7), TEXT(D23, "dddd"), IF(COUNTIF(Reference!$A$13:$A$27, D23) > 0, "Holiday", TEXT(D23, "dddd"))) -> Friday | C23: =TEXT(D23,"dddd") -> Friday | D23: 46164 | I23: =IFERROR((G23/H23)*60, "") | P23: =IF(ISBLANK(E23), "", TRANSPOSE(INDIRECT(E23)))
A24: =WEEKNUM(D24,2) -> 21 | B24: =IF(OR(WEEKDAY(D24)=1, WEEKDAY(D24)=7), TEXT(D24, "dddd"), IF(COUNTIF(Reference!$A$13:$A$27, D24) > 0, "Holiday", TEXT(D24, "dddd"))) -> Saturday | C24: =TEXT(D24,"dddd") -> Saturday | D24: 46165 | I24: =IFERROR((G24/H24)*60, "") | P24: =IF(ISBLANK(E24), "", TRANSPOSE(INDIRECT(E24)))
A25: =WEEKNUM(D25,2) -> 21 | B25: =IF(OR(WEEKDAY(D25)=1, WEEKDAY(D25)=7), TEXT(D25, "dddd"), IF(COUNTIF(Reference!$A$13:$A$27, D25) > 0, "Holiday", TEXT(D25, "dddd"))) -> Sunday | C25: =TEXT(D25,"dddd") -> Sunday | D25: 46166 | I25: =IFERROR((G25/H25)*60, "") | P25: =IF(ISBLANK(E25), "", TRANSPOSE(INDIRECT(E25)))
A26: =WEEKNUM(D26,2) -> 22 | B26: =IF(OR(WEEKDAY(D26)=1, WEEKDAY(D26)=7), TEXT(D26, "dddd"), IF(COUNTIF(Reference!$A$13:$A$27, D26) > 0, "Holiday", TEXT(D26, "dddd"))) -> Holiday | C26: =TEXT(D26,"dddd") -> Monday | D26: 46167 | I26: =IFERROR((G26/H26)*60, "") | P26: =IF(ISBLANK(E26), "", TRANSPOSE(INDIRECT(E26)))
A27: =WEEKNUM(D27,2) -> 22 | B27: =IF(OR(WEEKDAY(D27)=1, WEEKDAY(D27)=7), TEXT(D27, "dddd"), IF(COUNTIF(Reference!$A$13:$A$27, D27) > 0, "Holiday", TEXT(D27, "dddd"))) -> Tuesday | C27: =TEXT(D27,"dddd") -> Tuesday | D27: 46168 | E27: Topology_Coding | F27: Switzerland | G27: 8 | H27: 20 | I27: =IFERROR((G27/H27)*60, "") -> 24 | P27: =IF(ISBLANK(E27), "", TRANSPOSE(INDIRECT(E27))) -> Netherlands | Q27: Norway | R27: Switzerland | S27: UK
A28: =WEEKNUM(D28,2) -> 22 | B28: =IF(OR(WEEKDAY(D28)=1, WEEKDAY(D28)=7), TEXT(D28, "dddd"), IF(COUNTIF(Reference!$A$13:$A$27, D28) > 0, "Holiday", TEXT(D28, "dddd"))) -> Wednesday | C28: =TEXT(D28,"dddd") -> Wednesday | D28: 46169 | E28: Topology_Coding | F28: Switzerland | G28: 6 | H28: 15 | I28: =IFERROR((G28/H28)*60, "") -> 24 | P28: =IF(ISBLANK(E28), "", TRANSPOSE(INDIRECT(E28))) -> Netherlands | Q28: Norway | R28: Switzerland | S28: UK
A29: =WEEKNUM(D29,2) -> 22 | B29: =IF(OR(WEEKDAY(D29)=1, WEEKDAY(D29)=7), TEXT(D29, "dddd"), IF(COUNTIF(Reference!$A$13:$A$27, D29) > 0, "Holiday", TEXT(D29, "dddd"))) -> Thursday | C29: =TEXT(D29,"dddd") -> Thursday | D29: 46170 | E29: Topology_Coding | F29: Switzerland | G29: 6 | H29: 13 | I29: =IFERROR((G29/H29)*60, "") -> 27.692308 | P29: =IF(ISBLANK(E29), "", TRANSPOSE(INDIRECT(E29))) -> Netherlands | Q29: Norway | R29: Switzerland | S29: UK
A30: =WEEKNUM(D30,2) -> 22 | B30: =IF(OR(WEEKDAY(D30)=1, WEEKDAY(D30)=7), TEXT(D30, "dddd"), IF(COUNTIF(Reference!$A$13:$A$27, D30) > 0, "Holiday", TEXT(D30, "dddd"))) -> Friday | C30: =TEXT(D30,"dddd") -> Friday | D30: 46171 | I30: =IFERROR((G30/H30)*60, "") | P30: =IF(ISBLANK(E30), "", TRANSPOSE(INDIRECT(E30)))
A31: =WEEKNUM(D31,2) -> 22 | B31: =IF(OR(WEEKDAY(D31)=1, WEEKDAY(D31)=7), TEXT(D31, "dddd"), IF(COUNTIF(Reference!$A$13:$A$27, D31) > 0, "Holiday", TEXT(D31, "dddd"))) -> Saturday | C31: =TEXT(D31,"dddd") -> Saturday | D31: 46172 | I31: =IFERROR((G31/H31)*60, "") | P31: =IF(ISBLANK(E31), "", TRANSPOSE(INDIRECT(E31)))
A32: =WEEKNUM(D32,2) -> 22 | B32: =IF(OR(WEEKDAY(D32)=1, WEEKDAY(D32)=7), TEXT(D32, "dddd"), IF(COUNTIF(Reference!$A$13:$A$27, D32) > 0, "Holiday", TEXT(D32, "dddd"))) -> Sunday | C32: =TEXT(D32,"dddd") -> Sunday | D32: 46173 | I32: =IFERROR((G32/H32)*60, "") | P32: =IF(ISBLANK(E32), "", TRANSPOSE(INDIRECT(E32)))
A33: =WEEKNUM(D33,2) -> 23 | B33: =IF(OR(WEEKDAY(D33)=1, WEEKDAY(D33)=7), TEXT(D33, "dddd"), IF(COUNTIF(Reference!$A$13:$A$27, D33) > 0, "Holiday", TEXT(D33, "dddd"))) -> Monday | C33: =TEXT(D33,"dddd") -> Monday | D33: 46174 | E33: Topology_Coding | F33: Switzerland | G33: 6 | H33: 22 | I33: =IFERROR((G33/H33)*60, "") -> 16.363636 | P33: =IF(ISBLANK(E33), "", TRANSPOSE(INDIRECT(E33))) -> Netherlands | Q33: Norway | R33: Switzerland | S33: UK
A34: =WEEKNUM(D34,2) -> 23 | B34: =IF(OR(WEEKDAY(D34)=1, WEEKDAY(D34)=7), TEXT(D34, "dddd"), IF(COUNTIF(Reference!$A$13:$A$27, D34) > 0, "Holiday", TEXT(D34, "dddd"))) -> Tuesday | C34: =TEXT(D34,"dddd") -> Tuesday | D34: 46175 | E34: Topology_Coding | F34: Switzerland | G34: 8 | H34: 28 | I34: =IFERROR((G34/H34)*60, "") -> 17.142857 | P34: =IF(ISBLANK(E34), "", TRANSPOSE(INDIRECT(E34))) -> Netherlands | Q34: Norway | R34: Switzerland | S34: UK
A35: =WEEKNUM(D35,2) -> 23 | B35: =IF(OR(WEEKDAY(D35)=1, WEEKDAY(D35)=7), TEXT(D35, "dddd"), IF(COUNTIF(Reference!$A$13:$A$27, D35) > 0, "Holiday", TEXT(D35, "dddd"))) -> Wednesday | C35: =TEXT(D35,"dddd") -> Wednesday | D35: 46176 | E35: Topology_Coding | F35: UK | G35: 6 | H35: 20 | I35: =IFERROR((G35/H35)*60, "") -> 18 | P35: =IF(ISBLANK(E35), "", TRANSPOSE(INDIRECT(E35))) -> Netherlands | Q35: Norway | R35: Switzerland | S35: UK
A36: =WEEKNUM(D36,2) -> 23 | B36: =IF(OR(WEEKDAY(D36)=1, WEEKDAY(D36)=7), TEXT(D36, "dddd"), IF(COUNTIF(Reference!$A$13:$A$27, D36) > 0, "Holiday", TEXT(D36, "dddd"))) -> Holiday | C36: =TEXT(D36,"dddd") -> Thursday | D36: 46177 | I36: =IFERROR((G36/H36)*60, "") | P36: =IF(ISBLANK(E36), "", TRANSPOSE(INDIRECT(E36)))
A37: =WEEKNUM(D37,2) -> 23 | B37: =IF(OR(WEEKDAY(D37)=1, WEEKDAY(D37)=7), TEXT(D37, "dddd"), IF(COUNTIF(Reference!$A$13:$A$27, D37) > 0, "Holiday", TEXT(D37, "dddd"))) -> Friday | C37: =TEXT(D37,"dddd") -> Friday | D37: 46178 | I37: =IFERROR((G37/H37)*60, "") | P37: =IF(ISBLANK(E37), "", TRANSPOSE(INDIRECT(E37)))
A38: =WEEKNUM(D38,2) -> 23 | B38: =IF(OR(WEEKDAY(D38)=1, WEEKDAY(D38)=7), TEXT(D38, "dddd"), IF(COUNTIF(Reference!$A$13:$A$27, D38) > 0, "Holiday", TEXT(D38, "dddd"))) -> Saturday | C38: =TEXT(D38,"dddd") -> Saturday | D38: 46179 | I38: =IFERROR((G38/H38)*60, "") | P38: =IF(ISBLANK(E38), "", TRANSPOSE(INDIRECT(E38)))
A39: =WEEKNUM(D39,2) -> 23 | B39: =IF(OR(WEEKDAY(D39)=1, WEEKDAY(D39)=7), TEXT(D39, "dddd"), IF(COUNTIF(Reference!$A$13:$A$27, D39) > 0, "Holiday", TEXT(D39, "dddd"))) -> Sunday | C39: =TEXT(D39,"dddd") -> Sunday | D39: 46180 | I39: =IFERROR((G39/H39)*60, "") | P39: =IF(ISBLANK(E39), "", TRANSPOSE(INDIRECT(E39)))
A40: =WEEKNUM(D40,2) -> 24 | B40: =IF(OR(WEEKDAY(D40)=1, WEEKDAY(D40)=7), TEXT(D40, "dddd"), IF(COUNTIF(Reference!$A$13:$A$27, D40) > 0, "Holiday", TEXT(D40, "dddd"))) -> Monday | C40: =TEXT(D40,"dddd") -> Monday | D40: 46181 | E40: Topology_Coding | F40: UK | G40: 8 | H40: 15 | I40: =IFERROR((G40/H40)*60, "") -> 32 | P40: =IF(ISBLANK(E40), "", TRANSPOSE(INDIRECT(E40))) -> Netherlands | Q40: Norway | R40: Switzerland | S40: UK
...

Sheet Jigar
A1: KW | B1: Holiday OR Weekend | C1: Day | D1: Date | E1: Project | F1: Task | G1: Duration (Hrs) | H1: # of Signals | I1: Time per Signal (mins) | J1: Notes
A2: =WEEKNUM(D2,2) -> 18 | B2: =IF(OR(WEEKDAY(D2)=1, WEEKDAY(D2)=7), TEXT(D2, "dddd"), IF(COUNTIF(Reference!$A$13:$A$27, D2) > 0, "Holiday", TEXT(D2, "dddd"))) -> Holiday | C2: =TEXT(D2,"dddd") -> Friday | D2: 46143 | P2: =IF(ISBLANK(E2), "", TRANSPOSE(INDIRECT(E2)))
A3: =WEEKNUM(D3,2) -> 18 | B3: =IF(OR(WEEKDAY(D3)=1, WEEKDAY(D3)=7), TEXT(D3, "dddd"), IF(COUNTIF(Reference!$A$13:$A$27, D3) > 0, "Holiday", TEXT(D3, "dddd"))) -> Saturday | C3: =TEXT(D3,"dddd") -> Saturday | D3: 46144 | I3: =IFERROR((G3/H3)*60, "") | P3: =IF(ISBLANK(E3), "", TRANSPOSE(INDIRECT(E3)))
A4: =WEEKNUM(D4,2) -> 18 | B4: =IF(OR(WEEKDAY(D4)=1, WEEKDAY(D4)=7), TEXT(D4, "dddd"), IF(COUNTIF(Reference!$A$13:$A$27, D4) > 0, "Holiday", TEXT(D4, "dddd"))) -> Sunday | C4: =TEXT(D4,"dddd") -> Sunday | D4: 46145 | I4: =IFERROR((G4/H4)*60, "") | P4: =IF(ISBLANK(E4), "", TRANSPOSE(INDIRECT(E4)))
A5: =WEEKNUM(D5,2) -> 19 | B5: =IF(OR(WEEKDAY(D5)=1, WEEKDAY(D5)=7), TEXT(D5, "dddd"), IF(COUNTIF(Reference!$A$13:$A$27, D5) > 0, "Holiday", TEXT(D5, "dddd"))) -> Monday | C5: =TEXT(D5,"dddd") -> Monday | D5: 46146 | I5: =IFERROR((G5/H5)*60, "") | P5: =IF(ISBLANK(E5), "", TRANSPOSE(INDIRECT(E5)))
A6: =WEEKNUM(D6,2) -> 19 | B6: =IF(OR(WEEKDAY(D6)=1, WEEKDAY(D6)=7), TEXT(D6, "dddd"), IF(COUNTIF(Reference!$A$13:$A$27, D6) > 0, "Holiday", TEXT(D6, "dddd"))) -> Tuesday | C6: =TEXT(D6,"dddd") -> Tuesday | D6: 46147 | I6: =IFERROR((G6/H6)*60, "") | P6: =IF(ISBLANK(E6), "", TRANSPOSE(INDIRECT(E6)))
A7: =WEEKNUM(D7,2) -> 19 | B7: =IF(OR(WEEKDAY(D7)=1, WEEKDAY(D7)=7), TEXT(D7, "dddd"), IF(COUNTIF(Reference!$A$13:$A$27, D7) > 0, "Holiday", TEXT(D7, "dddd"))) -> Wednesday | C7: =TEXT(D7,"dddd") -> Wednesday | D7: 46148 | E7: Topology_Coding | F7: UK | G7: 5 | H7: =16+14 -> 30 | I7: =IFERROR((G7/H7)*60, "") -> 10 | P7: =IF(ISBLANK(E7), "", TRANSPOSE(INDIRECT(E7))) -> Netherlands | Q7: Norway | R7: Switzerland | S7: UK
A8: =WEEKNUM(D8,2) -> 19 | B8: =IF(OR(WEEKDAY(D8)=1, WEEKDAY(D8)=7), TEXT(D8, "dddd"), IF(COUNTIF(Reference!$A$13:$A$27, D8) > 0, "Holiday", TEXT(D8, "dddd"))) -> Thursday | C8: =TEXT(D8,"dddd") -> Thursday | D8: 46149 | E8: Topology_Coding | F8: UK | G8: 5 | H8: 63 | I8: =IFERROR((G8/H8)*60, "") -> 4.7619048 | P8: =IF(ISBLANK(E8), "", TRANSPOSE(INDIRECT(E8))) -> Netherlands | Q8: Norway | R8: Switzerland | S8: UK
A9: =WEEKNUM(D9,2) -> 19 | B9: =IF(OR(WEEKDAY(D9)=1, WEEKDAY(D9)=7), TEXT(D9, "dddd"), IF(COUNTIF(Reference!$A$13:$A$27, D9) > 0, "Holiday", TEXT(D9, "dddd"))) -> Friday | C9: =TEXT(D9,"dddd") -> Friday | D9: 46150 | I9: =IFERROR((G9/H9)*60, "") | P9: =IF(ISBLANK(E9), "", TRANSPOSE(INDIRECT(E9)))
A10: =WEEKNUM(D10,2) -> 19 | B10: =IF(OR(WEEKDAY(D10)=1, WEEKDAY(D10)=7), TEXT(D10, "dddd"), IF(COUNTIF(Reference!$A$13:$A$27, D10) > 0, "Holiday", TEXT(D10, "dddd"))) -> Saturday | C10: =TEXT(D10,"dddd") -> Saturday | D10: 46151 | I10: =IFERROR((G10/H10)*60, "") | P10: =IF(ISBLANK(E10), "", TRANSPOSE(INDIRECT(E10)))
A11: =WEEKNUM(D11,2) -> 19 | B11: =IF(OR(WEEKDAY(D11)=1, WEEKDAY(D11)=7), TEXT(D11, "dddd"), IF(COUNTIF(Reference!$A$13:$A$27, D11) > 0, "Holiday", TEXT(D11, "dddd"))) -> Sunday | C11: =TEXT(D11,"dddd") -> Sunday | D11: 46152 | I11: =IFERROR((G11/H11)*60, "") | P11: =IF(ISBLANK(E11), "", TRANSPOSE(INDIRECT(E11)))
A12: =WEEKNUM(D12,2) -> 20 | B12: =IF(OR(WEEKDAY(D12)=1, WEEKDAY(D12)=7), TEXT(D12, "dddd"), IF(COUNTIF(Reference!$A$13:$A$27, D12) > 0, "Holiday", TEXT(D12, "dddd"))) -> Monday | C12: =TEXT(D12,"dddd") -> Monday | D12: 46153 | I12: =IFERROR((G12/H12)*60, "") | P12: =IF(ISBLANK(E12), "", TRANSPOSE(INDIRECT(E12)))
